Workbook

Sheet NOTES
J1: EXPORT THE ON HAND DATA FROM THE INV -> REPORTING TAB WITH THE STOCK FILTER ENABLED | X1: DISCONTINUED | Y1: SKU | Z1: LINK
A2: Matte Finish Copper Mug. A festive gift. | B2: YS0004300000 | C2: COPPER | D2: FOR GIFTING 25 EACH | J2: MUST HAVE THE COLS IN THE RIGHT ENABLED FOR THIS EXPORT | X2: LB NOTEBOOK | Y2: HO0076400000 | Z2: https://ishalife.sadhguru.org/usa/linga-bhairavi-handcrafted-notebook
X3: Spatik Mala (Quartz Stones) | Y3: RS0001000100 | AA3: SMALLEST SIZE DKED
J4: THIS IS THE STOCK | X4: Isha Wooden Ball Pen | Y4: HO0079300000
J5: FOR THE SALES GO TO SALES REPORTING, LAST 365 DAYS SELECT ONLY THE QTY ORDEREDED AND MAKE THE LEFT SIDE THE EXPANDED PROD VARIANTS AND PASTE THAT AS IS | X5: Adiyogi Car Hanging | Y5: HO0088100000
A8: ORDER REMARKS | H8: Q2 ORDER REMARKS
A9: S No | B9: GLOBAL SKU | C9: NAME | D9: ORDER | E9: Remarks
A10: 1 | B10: HI0000600001 | C10: nilavembu tablets | D10: 1670 | E10: Need to confirm Import clearance
A11: 2 | B11: BC0002206001 | C11: turmeric face pack | D11: 175 | E11: Need to confirm Import clearance
A12: 3 | B12: HO0030800002 | C12: Instant Herbal Dhoop 20pcs | D12: 115 | E12: Previous orders were cancelled due to cow dung Ingredient
A13: 6 | B13: YS0008416900 | C13: Shivanga Kit with Mala | D13: 255 | E13: Currently we have dispatched Shivanga Kit with Rudraksh Mala (without Hundi & Vibhuti)-YS0019900000, Pls check and confirm the SKU
A20: DEVI SHAWL COTTON GOLD WRITING
A21: TC0004016600 | B21: ENGLISH
A22: TC0004000400 | B22: TAMIL
A29: DOES ISHA LIFE STILL SELL SANNIDH ITEMS, VIBHUTI, SHAWL, SUTRA, ETC
A30: add in clothing and t shirts
A31: NEW PRODS AT FLOOR / ONLINE CHECK
A32: PRICING CHECK
A34: brass plates for buddha lamps ?
A37: clear our the sun hats only the bucket hat
A50: FABRIC | B50: CODE | D50: PRINT | E50: P
A51: ORGANIC SATIN | B51: 1 | D51: NO PRINT | E51: N
A52: COTTEN LINEN | B52: 2
A53: COTTON GUAZE | B53: 3
A54: COTTON CREPE | B54: 4
A55: COTTON SLUB | B55: 5
A56: EYELET | B56: 6
A57: VOILE | B57: 7
A58: COTTON JERSEY | B58: 8

Sheet ORDER LIST
A1: US SKU | B1: NAME | C1: SKU | D1: CAT | E1: RETAIL PRICE | F1: SHIP | G1: SEA | H1: AIR | I1: SEA ROUND | J1: AIR ROUND | K1: SEA COST | L1: AIR COST | M1: AIR SHIP? | N1: SHIPPING COST BY AIR | O1: UNIT WEIGHT (G) | P1: PROFIT LOST BY AIR | Q1: MARGIN | R1: LEAD TIME (MONTHS) | S1: CASE
A2: {=XLOOKUP(C2,INV!D:D,INV!I:I)} -> BK107 | B2: {=XLOOKUP(C2,INV!A:A,INV!B:B)} -> Taste of Isha Cookbook | C2: ME0008101506 | D2: A & A | E2: {=XLOOKUP(C2,INV!A:A,INV!K:K)} -> 15 | F2: DOMESTIC | M2: {=XLOOKUP(C2,SEA!B:B,SEA!R:R)} -> #N/A
A3: {=XLOOKUP(C3,INV!D:D,INV!I:I)} -> HO0079300000 | B3: Isha Wooden Ball Pen | C3: HO0079300000 | D3: ACCESSORY | E3: {=XLOOKUP(C3,INV!A:A,INV!K:K)} -> 5 | G3: {=XLOOKUP(C3,SEA!B:B,SEA!Q:Q)} -> #N/A | H3: {=XLOOKUP(C3,SEA!B:B,SEA!S:S)} -> #N/A | I3: =CEILING(G3,S3) -> #N/A | J3: =CEILING(H3,S3) -> #N/A | K3: {=I3*XLOOKUP(C3,'PRICE LIST'!E:E,'PRICE LIST'!J:J)} -> #N/A | L3: {=J3*XLOOKUP(C3,'PRICE LIST'!E:E,'PRICE LIST'!J:J)} -> #N/A | M3: {=XLOOKUP(C3,SEA!B:B,SEA!R:R)} -> #N/A | P3: =Q3*J3 -> #N/A | Q3: {=E3-XLOOKUP(C3,'PRICE LIST'!E:E,'PRICE LIST'!J:J)} -> #N/A | S3: 1
A4: {=XLOOKUP(C4,INV!D:D,INV!I:I)} -> EX102 | B4: Adiyogi Car Hanging | C4: HO0088100000 | D4: ACCESSORY | E4: {=XLOOKUP(C4,INV!A:A,INV!K:K)} -> 5 | G4: {=XLOOKUP(C4,SEA!B:B,SEA!Q:Q)} -> #N/A | H4: {=XLOOKUP(C4,SEA!B:B,SEA!S:S)} -> #N/A | I4: =CEILING(G4,S4) -> #N/A | J4: =CEILING(H4,S4) -> #N/A | K4: {=I4*XLOOKUP(C4,'PRICE LIST'!E:E,'PRICE LIST'!J:J)} -> #N/A | L4: {=J4*XLOOKUP(C4,'PRICE LIST'!E:E,'PRICE LIST'!J:J)} -> #N/A | M4: {=XLOOKUP(C4,SEA!B:B,SEA!R:R)} -> #N/A | P4: =Q4*J4 -> #N/A | Q4: {=E4-XLOOKUP(C4,'PRICE LIST'!E:E,'PRICE LIST'!J:J)} -> 5 | S4: 1
A5: {=XLOOKUP(C5,INV!D:D,INV!I:I)} -> EX127 | B5: Car-Stand-Photo | C5: ME0016300000 | D5: ACCESSORY | E5: {=XLOOKUP(C5,INV!A:A,INV!K:K)} -> 5 | G5: {=XLOOKUP(C5,SEA!B:B,SEA!Q:Q)} -> 16.083333 | H5: {=XLOOKUP(C5,SEA!B:B,SEA!S:S)} -> 0 | I5: =CEILING(G5,S5) -> 17 | J5: =CEILING(H5,S5) -> 0 | K5: {=I5*XLOOKUP(C5,'PRICE LIST'!E:E,'PRICE LIST'!J:J)} -> #N/A | L5: {=J5*XLOOKUP(C5,'PRICE LIST'!E:E,'PRICE LIST'!J:J)} -> #N/A | M5: {=XLOOKUP(C5,SEA!B:B,SEA!R:R)} | P5: =Q5*J5 -> #N/A | Q5: {=E5-XLOOKUP(C5,'PRICE LIST'!E:E,'PRICE LIST'!J:J)} -> #N/A | S5: 1
A6: {=XLOOKUP(C6,INV!D:D,INV!I:I)} -> EX401 | B6: Adiyogi miniature 2" car stand - Black | C6: ME0037600000 | D6: ACCESSORY | E6: {=XLOOKUP(C6,INV!A:A,INV!K:K)} -> 15 | G6: {=XLOOKUP(C6,SEA!B:B,SEA!Q:Q)} -> 98.583333 | H6: {=XLOOKUP(C6,SEA!B:B,SEA!S:S)} -> 0 | I6: =CEILING(G6,S6) -> 99 | J6: =CEILING(H6,S6) -> 0 | K6: {=I6*XLOOKUP(C6,'PRICE LIST'!E:E,'PRICE LIST'!J:J)} -> 0 | L6: {=J6*XLOOKUP(C6,'PRICE LIST'!E:E,'PRICE LIST'!J:J)} -> 0 | M6: {=XLOOKUP(C6,SEA!B:B,SEA!R:R)} | P6: =Q6*J6 -> 0 | Q6: {=E6-XLOOKUP(C6,'PRICE LIST'!E:E,'PRICE LIST'!J:J)} -> 15 | S6: 1
A7: {=XLOOKUP(C7,INV!D:D,INV!I:I)} -> EX128 | B7: Devi-Car-Hanging | C7: ME0018900000 | D7: ACCESSORY | E7: {=XLOOKUP(C7,INV!A:A,INV!K:K)} -> 5 | G7: {=XLOOKUP(C7,SEA!B:B,SEA!Q:Q)} -> 131.75 | H7: {=XLOOKUP(C7,SEA!B:B,SEA!S:S)} -> 0 | I7: =CEILING(G7,S7) -> 132 | J7: =CEILING(H7,S7) -> 0 | K7: {=I7*XLOOKUP(C7,'PRICE LIST'!E:E,'PRICE LIST'!J:J)} -> 0 | L7: {=J7*XLOOKUP(C7,'PRICE LIST'!E:E,'PRICE LIST'!J:J)} -> 0 | M7: {=XLOOKUP(C7,SEA!B:B,SEA!R:R)} | P7: =Q7*J7 -> 0 | Q7: {=E7-XLOOKUP(C7,'PRICE LIST'!E:E,'PRICE LIST'!J:J)} -> 5 | S7: 1
A8: {=XLOOKUP(C8,INV!D:D,INV!I:I)} -> HO0108200000 | B8: Devi Journal (Tree free Banana Paper) | C8: HO0108200000 | D8: ACCESSORY | E8: {=XLOOKUP(C8,INV!A:A,INV!K:K)} -> 5 | G8: {=XLOOKUP(C8,SEA!B:B,SEA!Q:Q)} -> 30 | H8: {=XLOOKUP(C8,SEA!B:B,SEA!S:S)} -> 0 | I8: =CEILING(G8,S8) -> 30 | J8: =CEILING(H8,S8) -> 0 | K8: {=I8*XLOOKUP(C8,'PRICE LIST'!E:E,'PRICE LIST'!J:J)} -> 0 | L8: {=J8*XLOOKUP(C8,'PRICE LIST'!E:E,'PRICE LIST'!J:J)} -> 0 | M8: {=XLOOKUP(C8,SEA!B:B,SEA!R:R)} | P8: =Q8*J8 -> 0 | Q8: {=E8-XLOOKUP(C8,'PRICE LIST'!E:E,'PRICE LIST'!J:J)} -> 5 | S8: 1
A9: {=XLOOKUP(C9,INV!D:D,INV!I:I)} -> HO0088917200 | B9: Adiyogi Galactic - Printed Notebook | C9: HO0088917200 | D9: ACCESSORY | E9: {=XLOOKUP(C9,INV!A:A,INV!K:K)} -> 5 | G9: {=XLOOKUP(C9,SEA!B:B,SEA!Q:Q)} -> 20 | H9: {=XLOOKUP(C9,SEA!B:B,SEA!S:S)} -> 0 | I9: =CEILING(G9,S9) -> 20 | J9: =CEILING(H9,S9) -> 0 | K9: {=I9*XLOOKUP(C9,'PRICE LIST'!E:E,'PRICE LIST'!J:J)} -> 0 | L9: {=J9*XLOOKUP(C9,'PRICE LIST'!E:E,'PRICE LIST'!J:J)} -> 0 | M9: {=XLOOKUP(C9,SEA!B:B,SEA!R:R)} | P9: =Q9*J9 -> 0 | Q9: {=E9-XLOOKUP(C9,'PRICE LIST'!E:E,'PRICE LIST'!J:J)} -> 5 | S9: 1
A10: {=XLOOKUP(C10,INV!D:D,INV!I:I)} -> HO0125900000 | B10: Adiyogi Glow-in-the-Dark Keychain (hues of slendour) | C10: HO0125900000 | D10: ACCESSORY | E10: {=XLOOKUP(C10,INV!A:A,INV!K:K)} -> 4 | G10: {=XLOOKUP(C10,SEA!B:B,SEA!Q:Q)} -> 20 | H10: {=XLOOKUP(C10,SEA!B:B,SEA!S:S)} -> 0 | I10: =CEILING(G10,S10) -> 20 | J10: =CEILING(H10,S10) -> 0 | K10: {=I10*XLOOKUP(C10,'PRICE LIST'!E:E,'PRICE LIST'!J:J)} -> 0 | L10: {=J10*XLOOKUP(C10,'PRICE LIST'!E:E,'PRICE LIST'!J:J)} -> 0 | M10: {=XLOOKUP(C10,SEA!B:B,SEA!R:R)} | P10: =Q10*J10 -> 0 | Q10: {=E10-XLOOKUP(C10,'PRICE LIST'!E:E,'PRICE LIST'!J:J)} -> 4 | S10: 1
A11: {=XLOOKUP(C11,INV!D:D,INV!I:I)} -> HO0126100000 | B11: Linga Bhairavi Glow-in-the-Dark Keychain | C11: HO0126100000 | D11: ACCESSORY | E11: {=XLOOKUP(C11,INV!A:A,INV!K:K)} -> 4 | G11: {=XLOOKUP(C11,SEA!B:B,SEA!Q:Q)} -> 20 | H11: {=XLOOKUP(C11,SEA!B:B,SEA!S:S)} -> 0 | I11: =CEILING(G11,S11) -> 20 | J11: =CEILING(H11,S11) -> 0 | K11: {=I11*XLOOKUP(C11,'PRICE LIST'!E:E,'PRICE LIST'!J:J)} -> 0 | L11: {=J11*XLOOKUP(C11,'PRICE LIST'!E:E,'PRICE LIST'!J:J)} -> 0 | M11: {=XLOOKUP(C11,SEA!B:B,SEA!R:R)} | P11: =Q11*J11 -> 0 | Q11: {=E11-XLOOKUP(C11,'PRICE LIST'!E:E,'PRICE LIST'!J:J)} -> 4 | S11: 1
A12: {=XLOOKUP(C12,INV!D:D,INV!I:I)} -> BG162 | B12: Jute Canvas Backpack | C12: CA0000100000 | D12: ACCESSORY | E12: {=XLOOKUP(C12,INV!A:A,INV!K:K)} -> 19 | G12: {=XLOOKUP(C12,SEA!B:B,SEA!Q:Q)} -> 0 | H12: {=XLOOKUP(C12,SEA!B:B,SEA!S:S)} -> 0 | I12: =CEILING(G12,S12) -> 0 | J12: =CEILING(H12,S12) -> 0 | K12: {=I12*XLOOKUP(C12,'PRICE LIST'!E:E,'PRICE LIST'!J:J)} -> 0 | L12: {=J12*XLOOKUP(C12,'PRICE LIST'!E:E,'PRICE LIST'!J:J)} -> 0 | M12: {=XLOOKUP(C12,SEA!B:B,SEA!R:R)} | P12: =Q12*J12 -> 0 | Q12: {=E12-XLOOKUP(C12,'PRICE LIST'!E:E,'PRICE LIST'!J:J)} -> 19 | S12: 1
A13: {=XLOOKUP(C13,INV!D:D,INV!I:I)} -> EX274 | B13: Naga - Foil printed notebook | C13: HO0088916900 | D13: ACCESSORY | E13: {=XLOOKUP(C13,INV!A:A,INV!K:K)} -> 10 | G13: {=XLOOKUP(C13,SEA!B:B,SEA!Q:Q)} -> 0 | H13: {=XLOOKUP(C13,SEA!B:B,SEA!S:S)} -> 0 | I13: =CEILING(G13,S13) -> 0 | J13: =CEILING(H13,S13) -> 0 | K13: {=I13*XLOOKUP(C13,'PRICE LIST'!E:E,'PRICE LIST'!J:J)} -> 0 | L13: {=J13*XLOOKUP(C13,'PRICE LIST'!E:E,'PRICE LIST'!J:J)} -> 0 | M13: {=XLOOKUP(C13,SEA!B:B,SEA!R:R)} | P13: =Q13*J13 -> 0 | Q13: {=E13-XLOOKUP(C13,'PRICE LIST'!E:E,'PRICE LIST'!J:J)} -> 10 | S13: 1
A14: {=XLOOKUP(C14,INV!D:D,INV!I:I)} -> EX328 | B14: Infinite - Screen Printed Notebook | C14: HO0116117000 | D14: ACCESSORY | E14: {=XLOOKUP(C14,INV!A:A,INV!K:K)} -> 5 | G14: {=XLOOKUP(C14,SEA!B:B,SEA!Q:Q)} -> 0 | H14: {=XLOOKUP(C14,SEA!B:B,SEA!S:S)} -> 0 | I14: =CEILING(G14,S14) -> 0 | J14: =CEILING(H14,S14) -> 0 | K14: {=I14*XLOOKUP(C14,'PRICE LIST'!E:E,'PRICE LIST'!J:J)} -> 0 | L14: {=J14*XLOOKUP(C14,'PRICE LIST'!E:E,'PRICE LIST'!J:J)} -> 0 | M14: {=XLOOKUP(C14,SEA!B:B,SEA!R:R)} | P14: =Q14*J14 -> 0 | Q14: {=E14-XLOOKUP(C14,'PRICE LIST'!E:E,'PRICE LIST'!J:J)} -> 5 | S14: 1
... A18: {=XLOOKUP(C18,INV!D:D,INV!I:I)} -> EX327 | B18: Linga Bhairavi Metal Keychain | C18: HO0110400000 | D18: ACCESSORY | E18: {=XLOOKUP(C18,INV!A:A,INV!K:K)} -> 3 | G18: {=XLOOKUP(C18,SEA!B:B,SEA!Q:Q)} -> 0 | H18: {=XLOOKUP(C18,SEA!B:B,SEA!S:S)} -> 0 | I18: =CEILING(G18,S18) -> 0 | J18: =CEILING(H18,S18) -> 0 | K18: {=I18*XLOOKUP(C18,'PRICE LIST'!E:E,'PRICE LIST'!J:J)} -> 0 | L18: {=J18*XLOOKUP(C18,'PRICE LIST'!E:E,'PRICE LIST'!J:J)} -> 0 | M18: {=XLOOKUP(C18,SEA!B:B,SEA!R:R)} | P18: =Q18*J18 -> 0 | Q18: {=E18-XLOOKUP(C18,'PRICE LIST'!E:E,'PRICE LIST'!J:J)} -> 3 | S18: 1
A19: {=XLOOKUP(C19,INV!D:D,INV!I:I)} -> RJ201-150 | B19: Herbal-Toothpaste | C19: BC0000706502 | D19: BODY CARE | E19: {=XLOOKUP(C19,INV!A:A,INV!K:K)} -> 8 | F19: TOOTHPASTE | G19: {=XLOOKUP(C19,UNIQUE!B:B,UNIQUE!I:I)} -> 8056 | I19: =CEILING(G19,S19) -> 8056 | J19: =CEILING(H19,S19) -> 0 | K19: {=I19*XLOOKUP(C19,'PRICE LIST'!E:E,'PRICE LIST'!J:J)} -> 0 | L19: {=J19*XLOOKUP(C19,'PRICE LIST'!E:E,'PRICE LIST'!J:J)} -> 0 | M19: {=XLOOKUP(C19,SEA!B:B,SEA!R:R)} -> #N/A | S19: 1
A20: {=XLOOKUP(C20,INV!D:D,INV!I:I)} -> BC227 | B20: Shikakai & Jatamansi Certified Organic Strengthening Shampoo - 200ml (Bloom) | C20: BC0003503302 | D20: BODY CARE | E20: {=XLOOKUP(C20,INV!A:A,INV!K:K)} -> 21 | F20: BLOOM | G20: {=XLOOKUP(C20,BLOOM!B:B,BLOOM!J:J)} -> #N/A | H20: {=XLOOKUP(C20,BLOOM!B:B,BLOOM!L:L)} -> #N/A | I20: =CEILING(G20,S20) -> #N/A | J20: =CEILING(H20,S20) -> #N/A | K20: {=I20*XLOOKUP(C20,'PRICE LIST'!E:E,'PRICE LIST'!J:J)} -> #N/A | L20: {=J20*XLOOKUP(C20,'PRICE LIST'!E:E,'PRICE LIST'!J:J)} -> #N/A | M20: {=XLOOKUP(C20,SEA!B:B,SEA!R:R)} -> #N/A | S20: 24
A21: {=XLOOKUP(C21,INV!D:D,INV!I:I)} -> BC221 | B21: Saffron & Sandalwood Certified Organic Refreshing Shower Gel - 200ml (Bloom) - Cosmos Organic certified by Ecocert Greenlife | C21: BC0002403302 | D21: BODY CARE | E21: {=XLOOKUP(C21,INV!A:A,INV!K:K)} -> 21 | F21: BLOOM | G21: {=XLOOKUP(C21,BLOOM!B:B,BLOOM!J:J)} -> #N/A | H21: {=XLOOKUP(C21,BLOOM!B:B,BLOOM!L:L)} -> #N/A | I21: =CEILING(G21,S21) -> #N/A | J21: =CEILING(H21,S21) -> #N/A | K21: {=I21*XLOOKUP(C21,'PRICE LIST'!E:E,'PRICE LIST'!J:J)} -> #N/A | L21: {=J21*XLOOKUP(C21,'PRICE LIST'!E:E,'PRICE LIST'!J:J)} -> #N/A | M21: {=XLOOKUP(C21,SEA!B:B,SEA!R:R)} -> #N/A | S21: 24
A22: {=XLOOKUP(C22,INV!D:D,INV!I:I)} -> BC231 | B22: Argan & Acai Organic Restorative Hair Oil - 100ml (Bloom) | C22: BC0003803102 | D22: BODY CARE | E22: {=XLOOKUP(C22,INV!A:A,INV!K:K)} -> 18 | F22: BLOOM | G22: {=XLOOKUP(C22,BLOOM!B:B,BLOOM!J:J)} -> #N/A | H22: {=XLOOKUP(C22,BLOOM!B:B,BLOOM!L:L)} -> #N/A | I22: =CEILING(G22,S22) -> #N/A | J22: =CEILING(H22,S22) -> #N/A | K22: {=I22*XLOOKUP(C22,'PRICE LIST'!E:E,'PRICE LIST'!J:J)} -> #N/A | L22: {=J22*XLOOKUP(C22,'PRICE LIST'!E:E,'PRICE LIST'!J:J)} -> #N/A | M22: {=XLOOKUP(C22,SEA!B:B,SEA!R:R)} -> #N/A | S22: 24
A23: {=XLOOKUP(C23,INV!D:D,INV!I:I)} -> BC223 | B23: Hibiscus & Aloe Vera Organic Moisturizing Body Lotion - 100ml (Bloom) | C23: BC0002603102 | D23: BODY CARE | E23: {=XLOOKUP(C23,INV!A:A,INV!K:K)} -> 15 | F23: BLOOM | G23: {=XLOOKUP(C23,BLOOM!B:B,BLOOM!J:J)} -> #N/A | H23: {=XLOOKUP(C23,BLOOM!B:B,BLOOM!L:L)} -> #N/A | I23: =CEILING(G23,S23) -> #N/A | J23: =CEILING(H23,S23) -> #N/A | K23: {=I23*XLOOKUP(C23,'PRICE LIST'!E:E,'PRICE LIST'!J:J)} -> #N/A | L23: {=J23*XLOOKUP(C23,'PRICE LIST'!E:E,'PRICE LIST'!J:J)} -> #N/A | M23: {=XLOOKUP(C23,SEA!B:B,SEA!R:R)} -> #N/A | S23: 24
A24: {=XLOOKUP(C24,INV!D:D,INV!I:I)} -> RJ201-50 | B24: Herbal-Toothpaste | C24: BC0000706002 | D24: BODY CARE | E24: {=XLOOKUP(C24,INV!A:A,INV!K:K)} -> 4 | F24: TOOTHPASTE | G24: {=XLOOKUP(C24,UNIQUE!B:B,UNIQUE!I:I)} -> 2400 | I24: =CEILING(G24,S24) -> 2400 | J24: =CEILING(H24,S24) -> 0 | K24: {=I24*XLOOKUP(C24,'PRICE LIST'!E:E,'PRICE LIST'!J:J)} -> 0 | L24: {=J24*XLOOKUP(C24,'PRICE LIST'!E:E,'PRICE LIST'!J:J)} -> 0 | M24: {=XLOOKUP(C24,SEA!B:B,SEA!R:R)} -> #N/A | S24: 1
A25: {=XLOOKUP(C25,INV!D:D,INV!I:I)} -> BC236 | B25: Sandalwood and Turmeric Face Wash 100 ml (Bloom) | C25: BC0003003102 | D25: BODY CARE | E25: {=XLOOKUP(C25,INV!A:A,INV!K:K)} -> 14 | F25: BLOOM | G25: {=XLOOKUP(C25,BLOOM!B:B,BLOOM!J:J)} -> #N/A | H25: {=XLOOKUP(C25,BLOOM!B:B,BLOOM!L:L)} -> #N/A | I25: =CEILING(G25,S25) -> #N/A | J25: =CEILING(H25,S25) -> #N/A | K25: {=I25*XLOOKUP(C25,'PRICE LIST'!E:E,'PRICE LIST'!J:J)} -> #N/A | L25: {=J25*XLOOKUP(C25,'PRICE LIST'!E:E,'PRICE LIST'!J:J)} -> #N/A | S25: 24
A26: {=XLOOKUP(C26,INV!D:D,INV!I:I)} -> BC225 | B26: Neem & Tulsi Certified Organic Cleansing Face Wash - 100ml (Bloom) | C26: BC0002903102 | D26: BODY CARE | E26: {=XLOOKUP(C26,INV!A:A,INV!K:K)} -> 14 | F26: BLOOM | G26: {=XLOOKUP(C26,BLOOM!B:B,BLOOM!J:J)} -> #N/A | H26: {=XLOOKUP(C26,BLOOM!B:B,BLOOM!L:L)} -> #N/A | I26: =CEILING(G26,S26) -> #N/A | J26: =CEILING(H26,S26) -> #N/A | K26: {=I26*XLOOKUP(C26,'PRICE LIST'!E:E,'PRICE LIST'!J:J)} -> #N/A | L26: {=J26*XLOOKUP(C26,'PRICE LIST'!E:E,'PRICE LIST'!J:J)} -> #N/A | M26: {=XLOOKUP(C26,SEA!B:B,SEA!R:R)} -> #N/A | S26: 24
A27: {=XLOOKUP(C27,INV!D:D,INV!I:I)} -> BC233 | B27: US Bloom 24 Hours Organic Body Lotion (Extra Dry Skin) (100 ml) | C27: BC0002703102 | D27: BODY CARE | E27: {=XLOOKUP(C27,INV!A:A,INV!K:K)} -> 15 | F27: BLOOM | G27: {=XLOOKUP(C27,BLOOM!B:B,BLOOM!J:J)} -> #N/A | H27: {=XLOOKUP(C27,BLOOM!B:B,BLOOM!L:L)} -> #N/A | I27: =CEILING(G27,S27) -> #N/A | J27: =CEILING(H27,S27) -> #N/A | K27: {=I27*XLOOKUP(C27,'PRICE LIST'!E:E,'PRICE LIST'!J:J)} -> #N/A | L27: {=J27*XLOOKUP(C27,'PRICE LIST'!E:E,'PRICE LIST'!J:J)} -> #N/A | S27: 24
A28: {=XLOOKUP(C28,INV!D:D,INV!I:I)} -> BC229 | B28: Hibiscus & Grapeseed Organic Strengthening Conditioner - 100ml (Bloom) | C28: BC0003603102 | D28: BODY CARE | E28: {=XLOOKUP(C28,INV!A:A,INV!K:K)} -> 15 | F28: BLOOM | G28: {=XLOOKUP(C28,BLOOM!B:B,BLOOM!J:J)} -> #N/A | H28: {=XLOOKUP(C28,BLOOM!B:B,BLOOM!L:L)} -> #N/A | I28: =CEILING(G28,S28) -> #N/A | J28: =CEILING(H28,S28) -> #N/A | K28: {=I28*XLOOKUP(C28,'PRICE LIST'!E:E,'PRICE LIST'!J:J)} -> #N/A | L28: {=J28*XLOOKUP(C28,'PRICE LIST'!E:E,'PRICE LIST'!J:J)} -> #N/A | S28: 24
A29: {=XLOOKUP(C29,INV!D:D,INV!I:I)} -> BC234 | B29: US Bloom Refreshing & Age Defence Shower Gel (200 ml) | C29: BC0002803302 | D29: BODY CARE | E29: {=XLOOKUP(C29,INV!A:A,INV!K:K)} -> 21 | F29: BLOOM | G29: {=XLOOKUP(C29,BLOOM!B:B,BLOOM!J:J)} -> #N/A | H29: {=XLOOKUP(C29,BLOOM!B:B,BLOOM!L:L)} -> #N/A | I29: =CEILING(G29,S29) -> #N/A | J29: =CEILING(H29,S29) -> #N/A | K29: {=I29*XLOOKUP(C29,'PRICE LIST'!E:E,'PRICE LIST'!J:J)} -> #N/A | L29: {=J29*XLOOKUP(C29,'PRICE LIST'!E:E,'PRICE LIST'!J:J)} -> #N/A | S29: 24
A30: {=XLOOKUP(C30,INV!D:D,INV!I:I)} -> BC220 | B30: Saffron & Sandalwood Certified Organic Refreshing Shower Gel - 30ml (Bloom) | C30: BC0002403002 | D30: BODY CARE | E30: {=XLOOKUP(C30,INV!A:A,INV!K:K)} -> 7 | F30: BLOOM | G30: {=XLOOKUP(C30,BLOOM!B:B,BLOOM!J:J)} -> #N/A | H30: {=XLOOKUP(C30,BLOOM!B:B,BLOOM!L:L)} -> #N/A | I30: =CEILING(G30,S30) -> #N/A | J30: =CEILING(H30,S30) -> #N/A | K30: {=I30*XLOOKUP(C30,'PRICE LIST'!E:E,'PRICE LIST'!J:J)} -> #N/A | L30: {=J30*XLOOKUP(C30,'PRICE LIST'!E:E,'PRICE LIST'!J:J)} -> #N/A | S30: 32
A31: {=XLOOKUP(C31,INV!D:D,INV!I:I)} -> BC222 | B31: Hibiscus & Aloe Vera Organic Moisturizing Body Lotion - 30ml (Bloom) | C31: BC0002603002 | D31: BODY CARE | E31: {=XLOOKUP(C31,INV!A:A,INV!K:K)} -> 7 | F31: BLOOM | G31: {=XLOOKUP(C31,BLOOM!B:B,BLOOM!J:J)} -> #N/A | H31: {=XLOOKUP(C31,BLOOM!B:B,BLOOM!L:L)} -> #N/A | I31: =CEILING(G31,S31) -> #N/A | J31: =CEILING(H31,S31) -> #N/A | K31: {=I31*XLOOKUP(C31,'PRICE LIST'!E:E,'PRICE LIST'!J:J)} -> #N/A | L31: {=J31*XLOOKUP(C31,'PRICE LIST'!E:E,'PRICE LIST'!J:J)} -> #N/A | S31: 32
A32: {=XLOOKUP(C32,INV!D:D,INV!I:I)} -> BC228 | B32: Hibiscus & Grapeseed Organic Strengthening Conditioner - 30ml (Bloom) | C32: BC0003603002 | D32: BODY CARE | E32: {=XLOOKUP(C32,INV!A:A,INV!K:K)} -> 7 | F32: BLOOM | G32: {=XLOOKUP(C32,BLOOM!B:B,BLOOM!J:J)} -> #N/A | H32: {=XLOOKUP(C32,BLOOM!B:B,BLOOM!L:L)} -> #N/A | I32: =CEILING(G32,S32) -> #N/A | J32: =CEILING(H32,S32) -> #N/A | K32: {=I32*XLOOKUP(C32,'PRICE LIST'!E:E,'PRICE LIST'!J:J)} -> #N/A | L32: {=J32*XLOOKUP(C32,'PRICE LIST'!E:E,'PRICE LIST'!J:J)} -> #N/A | S32: 32
A33: {=XLOOKUP(C33,INV!D:D,INV!I:I)} -> BC226 | B33: Shikakai & Jatamansi Certified Organic Strengthening Shampoo - 30ml (Bloom) | C33: BC0003503002 | D33: BODY CARE | E33: {=XLOOKUP(C33,INV!A:A,INV!K:K)} -> 7 | F33: BLOOM | G33: {=XLOOKUP(C33,BLOOM!B:B,BLOOM!J:J)} -> #N/A | H33: {=XLOOKUP(C33,BLOOM!B:B,BLOOM!L:L)} -> #N/A | I33: =CEILING(G33,S33) -> #N/A | J33: =CEILING(H33,S33) -> #N/A | K33: {=I33*XLOOKUP(C33,'PRICE LIST'!E:E,'PRICE LIST'!J:J)} -> #N/A | L33: {=J33*XLOOKUP(C33,'PRICE LIST'!E:E,'PRICE LIST'!J:J)} -> #N/A | S33: 32
A34: {=XLOOKUP(C34,INV!D:D,INV!I:I)} -> BC235 | B34: Sandalwood and Turmeric Face Wash 30ml (Bloom) | C34: BC0003003002 | D34: BODY CARE | E34: {=XLOOKUP(C34,INV!A:A,INV!K:K)} -> 7 | F34: BLOOM | G34: {=XLOOKUP(C34,BLOOM!B:B,BLOOM!J:J)} -> #N/A | H34: {=XLOOKUP(C34,BLOOM!B:B,BLOOM!L:L)} -> #N/A | I34: =CEILING(G34,S34) -> #N/A | J34: =CEILING(H34,S34) -> #N/A | K34: {=I34*XLOOKUP(C34,'PRICE LIST'!E:E,'PRICE LIST'!J:J)} -> #N/A | L34: {=J34*XLOOKUP(C34,'PRICE LIST'!E:E,'PRICE LIST'!J:J)} -> #N/A | S34: 32
A35: {=XLOOKUP(C35,INV!D:D,INV!I:I)} -> BC230 | B35: Argan & Acai Organic Restorative Hair Oil - 30ml (Bloom) | C35: BC0003803002 | D35: BODY CARE | E35: {=XLOOKUP(C35,INV!A:A,INV!K:K)} -> 7 | F35: BLOOM | G35: {=XLOOKUP(C35,BLOOM!B:B,BLOOM!J:J)} -> #N/A | H35: {=XLOOKUP(C35,BLOOM!B:B,BLOOM!L:L)} -> #N/A | I35: =CEILING(G35,S35) -> #N/A | J35: =CEILING(H35,S35) -> #N/A | K35: {=I35*XLOOKUP(C35,'PRICE LIST'!E:E,'PRICE LIST'!J:J)} -> #N/A | L35: {=J35*XLOOKUP(C35,'PRICE LIST'!E:E,'PRICE LIST'!J:J)} -> #N/A | S35: 32
A36: {=XLOOKUP(C36,INV!D:D,INV!I:I)} -> BC224 | B36: Neem & Tulsi Certified Organic Cleansing Face Wash - 30ml (Bloom) | C36: BC0002903002 | D36: BODY CARE | E36: {=XLOOKUP(C36,INV!A:A,INV!K:K)} -> 7 | F36: BLOOM | G36: {=XLOOKUP(C36,BLOOM!B:B,BLOOM!J:J)} -> #N/A | H36: {=XLOOKUP(C36,BLOOM!B:B,BLOOM!L:L)} -> #N/A | I36: =CEILING(G36,S36) -> #N/A | J36: =CEILING(H36,S36) -> #N/A | K36: {=I36*XLOOKUP(C36,'PRICE LIST'!E:E,'PRICE LIST'!J:J)} -> #N/A | L36: {=J36*XLOOKUP(C36,'PRICE LIST'!E:E,'PRICE LIST'!J:J)} -> #N/A | S36: 32
A37: {=XLOOKUP(C37,INV!D:D,INV!I:I)} -> BC501 | B37: Jasmine Orient Solid Perfume | C37: BC0001005100 | D37: BODY CARE | E37: {=XLOOKUP(C37,INV!A:A,INV!K:K)} -> 15 | G37: {=XLOOKUP(C37,SEA!B:B,SEA!Q:Q)} -> 68.5 | H37: {=XLOOKUP(C37,SEA!B:B,SEA!S:S)} -> 0 | I37: =CEILING(G37,S37) -> 69 | J37: =CEILING(H37,S37) -> 0 | K37: {=I37*XLOOKUP(C37,'PRICE LIST'!E:E,'PRICE LIST'!J:J)} -> 0 | L37: {=J37*XLOOKUP(C37,'PRICE LIST'!E:E,'PRICE LIST'!J:J)} -> 0 | M37: {=XLOOKUP(C37,SEA!B:B,SEA!R:R)} | P37: =Q37*J37 -> 0 | Q37: {=E37-XLOOKUP(C37,'PRICE LIST'!E:E,'PRICE LIST'!J:J)} -> 15 | S37: 1
A38: {=XLOOKUP(C38,INV!D:D,INV!I:I)} -> RJ203-100 | B38: Ojasvini 100g | C38: BC0002006302 | D38: BODY CARE | E38: {=XLOOKUP(C38,INV!A:A,INV!K:K)} -> 8 | F38: EXPIRY | G38: {=XLOOKUP(C38,SEA!B:B,SEA!Q:Q)} -> #N/A | H38: {=XLOOKUP(C38,SEA!B:B,SEA!S:S)} -> #N/A | I38: =CEILING(G38,S38) -> #N/A | J38: =CEILING(H38,S38) -> #N/A | K38: {=I38*XLOOKUP(C38,'PRICE LIST'!E:E,'PRICE LIST'!J:J)} -> #N/A | L38: {=J38*XLOOKUP(C38,'PRICE LIST'!E:E,'PRICE LIST'!J:J)} -> #N/A | M38: {=XLOOKUP(C38,SEA!B:B,SEA!R:R)} | P38: =Q38*J38 -> #N/A | Q38: {=E38-XLOOKUP(C38,'PRICE LIST'!E:E,'PRICE LIST'!J:J)} -> 8 | S38: 1
A39: {=XLOOKUP(C39,INV!D:D,INV!I:I)} -> EX141 | B39: NeemWoodComb-DualEnd | C39: BC0000400002 | D39: BODY CARE | E39: {=XLOOKUP(C39,INV!A:A,INV!K:K)} -> 7 | G39: {=XLOOKUP(C39,SEA!B:B,SEA!Q:Q)} -> 84.333333 | H39: {=XLOOKUP(C39,SEA!B:B,SEA!S:S)} -> 0 | I39: =CEILING(G39,S39) -> 85 | J39: =CEILING(H39,S39) -> 0 | K39: {=I39*XLOOKUP(C39,'PRICE LIST'!E:E,'PRICE LIST'!J:J)} -> 0 | L39: {=J39*XLOOKUP(C39,'PRICE LIST'!E:E,'PRICE LIST'!J:J)} -> 0 | M39: {=XLOOKUP(C39,SEA!B:B,SEA!R:R)} | P39: =Q39*J39 -> 0 | Q39: {=E39-XLOOKUP(C39,'PRICE LIST'!E:E,'PRICE LIST'!J:J)} -> 7 | S39: 1
A40: {=XLOOKUP(C40,INV!D:D,INV!I:I)} -> BC503 | B40: Relax Solid Perfume | C40: BC0001205100 | D40: BODY CARE | E40: {=XLOOKUP(C40,INV!A:A,INV!K:K)} -> 15 | G40: {=XLOOKUP(C40,SEA!B:B,SEA!Q:Q)} -> 34.75 | H40: {=XLOOKUP(C40,SEA!B:B,SEA!S:S)} -> 0 | I40: =CEILING(G40,S40) -> 35 | J40: =CEILING(H40,S40) -> 0 | K40: {=I40*XLOOKUP(C40,'PRICE LIST'!E:E,'PRICE LIST'!J:J)} -> 0 | L40: {=J40*XLOOKUP(C40,'PRICE LIST'!E:E,'PRICE LIST'!J:J)} -> 0 | M40: {=XLOOKUP(C40,SEA!B:B,SEA!R:R)} | P40: =Q40*J40 -> 0 | Q40: {=E40-XLOOKUP(C40,'PRICE LIST'!E:E,'PRICE LIST'!J:J)} -> 15 | S40: 1
A41: {=XLOOKUP(C41,INV!D:D,INV!I:I)} -> BC504 | B41: Royal Oud Solid Perfume | C41: BC0001305100 | D41: BODY CARE | E41: {=XLOOKUP(C41,INV!A:A,INV!K:K)} -> 15 | G41: {=XLOOKUP(C41,SEA!B:B,SEA!Q:Q)} -> 19.916667 | H41: {=XLOOKUP(C41,SEA!B:B,SEA!S:S)} -> 0 | I41: =CEILING(G41,S41) -> 20 | J41: =CEILING(H41,S41) -> 0 | K41: {=I41*XLOOKUP(C41,'PRICE LIST'!E:E,'PRICE LIST'!J:J)} -> 0 | L41: {=J41*XLOOKUP(C41,'PRICE LIST'!E:E,'PRICE LIST'!J:J)} -> 0 | M41: {=XLOOKUP(C41,SEA!B:B,SEA!R:R)} | P41: =Q41*J41 -> 0 | Q41: {=E41-XLOOKUP(C41,'PRICE LIST'!E:E,'PRICE LIST'!J:J)} -> 15 | S41: 1
A42: {=XLOOKUP(C42,INV!D:D,INV!I:I)} -> EX114 | B42: NeemWoodComb-Handle-NarrowTeeth | C42: BC0000200002 | D42: BODY CARE | E42: {=XLOOKUP(C42,INV!A:A,INV!K:K)} -> 7 | G42: {=XLOOKUP(C42,SEA!B:B,SEA!Q:Q)} -> 36.166667 | H42: {=XLOOKUP(C42,SEA!B:B,SEA!S:S)} -> 0 | I42: =CEILING(G42,S42) -> 37 | J42: =CEILING(H42,S42) -> 0 | K42: {=I42*XLOOKUP(C42,'PRICE LIST'!E:E,'PRICE LIST'!J:J)} -> 0 | L42: {=J42*XLOOKUP(C42,'PRICE LIST'!E:E,'PRICE LIST'!J:J)} -> 0 | M42: {=XLOOKUP(C42,SEA!B:B,SEA!R:R)} | P42: =Q42*J42 -> 0 | Q42: {=E42-XLOOKUP(C42,'PRICE LIST'!E:E,'PRICE LIST'!J:J)} -> 7 | S42: 1
A43: {=XLOOKUP(C43,INV!D:D,INV!I:I)} -> EX197-S | B43: Organic Waffle Towel - Small | C43: CA0009100200 | D43: BODY CARE | E43: {=XLOOKUP(C43,INV!A:A,INV!K:K)} -> 5 | G43: {=XLOOKUP(C43,SEA!B:B,SEA!Q:Q)} -> 14 | H43: {=XLOOKUP(C43,SEA!B:B,SEA!S:S)} -> 0 | I43: =CEILING(G43,S43) -> 14 | J43: =CEILING(H43,S43) -> 0 | K43: {=I43*XLOOKUP(C43,'PRICE LIST'!E:E,'PRICE LIST'!J:J)} -> 0 | L43: {=J43*XLOOKUP(C43,'PRICE LIST'!E:E,'PRICE LIST'!J:J)} -> 0 | M43: {=XLOOKUP(C43,SEA!B:B,SEA!R:R)} | P43: =Q43*J43 -> 0 | Q43: {=E43-XLOOKUP(C43,'PRICE LIST'!E:E,'PRICE LIST'!J:J)} -> 5 | S43: 1
...

Sheet UNIQUE
A1: NAME | B1: SKU | C1: CAT | D1: ORDER | E1: MON SALES | F1: INV ON HAND | G1: MONTHS ON HAND | H1: MIN MOH | I1: QTY ORDER | J1: ROUND | K1: CASE
A2: Devi-Camphor | B2: HO0072400000 | C2: TEMPLE | D2: 12 | E2: {=XLOOKUP(B2,SALES!A:A,SALES!E:E)/12} -> 464.25 | F2: {=XLOOKUP(B2,INV!A:A,INV!G:G)} -> 3722 | G2: =F2/E2 -> 8.0172321 | H2: 9 | I2: =D2*E2 -> 5571 | J2: =CEILING(I2,K2) -> 5580 | K2: 60
A3: Camphor-Bhuta-Shuddhi-3-month-supply | B3: YS0007500000 | C3: YOGA STORE | D3: =IF(G3<H3,12,0) -> 12 | E3: {=XLOOKUP(B3,SALES!A:A,SALES!E:E)/12} -> 199 | F3: {=XLOOKUP(B3,INV!A:A,INV!G:G)} -> 1386 | G3: =F3/E3 -> 6.9648241 | H3: 9 | I3: =D3*E3 -> 2388 | J3: =CEILING(I3,K3) -> 2400 | K3: 100
A4: Herbal-Toothpaste | B4: BC0000706002 | C4: BODY CARE | D4: 24 | E4: 100 | F4: {=XLOOKUP(B4,INV!A:A,INV!G:G)} -> 0 | G4: =F4/E4 -> 0 | H4: 9 | I4: =D4*E4 -> 2400 | J4: =CEILING(I4,K4) -> 0
A5: Herbal-Toothpaste | B5: BC0000706502 | C5: BODY CARE | D5: 24 | E5: {=XLOOKUP(B5,SALES!A:A,SALES!E:E)/12} -> 335.66667 | F5: {=XLOOKUP(B5,INV!A:A,INV!G:G)} -> 510 | G5: =F5/E5 -> 1.5193644 | H5: 9 | I5: =D5*E5 -> 8056 | J5: =CEILING(I5,K5) -> 0
A14: WHEN ORDERING CAMPHOR WE MUST CHECK WITH TEMPLE TEAM IF THEY ALSO WANT TO ORDER THE BIG ROUND CAMPHOR ALONG WITH US
A15: THE INDIAN SKU FOR THAT IS 0119730

Sheet BLOOM
A1: NAME | B1: SKU | C1: CAT | D1: QTY SEA ROUND | E1: QTY AIR ROUND | F1: MON SALES | G1: MOH | H1: MIN MOH | I1: SEA | J1: QTY SEA | K1: AIR | L1: QTY AIR | M1: CASE SIZE
A2: Saffron & Sandalwood Certified Organic Refreshing Shower Gel - 30ml (Bloom) | B2: BC0002403002 | C2: BODY CARE | D2: =CEILING(J2,M2) -> #N/A | E2: =CEILING(L2,M2) -> #N/A | F2: {=XLOOKUP(B2,SALES!A:A,SALES!E:E)/12} -> 46.166667 | G2: {=XLOOKUP(B2,'EXP INV'!Q:Q,'EXP INV'!R:R)} -> #N/A | H2: 8 | I2: =IF(G2<H2,10,0) -> #N/A | J2: =I2*F2 -> #N/A | K2: =IF(G2-5<0,3,0) -> #N/A | L2: =K2*F2 -> #N/A | M2: 32
A3: Saffron & Sandalwood Certified Organic Refreshing Shower Gel - 200ml (Bloom) - Cosmos Organic certified by Ecocert Greenlife | B3: BC0002403302 | C3: BODY CARE | D3: =CEILING(J3,M3) -> #N/A | E3: =CEILING(L3,M3) -> #N/A | F3: {=XLOOKUP(B3,SALES!A:A,SALES!E:E)/12} -> 66.916667 | G3: {=XLOOKUP(B3,'EXP INV'!Q:Q,'EXP INV'!R:R)} -> #N/A | H3: 8 | I3: =IF(G3<H3,10,0) -> #N/A | J3: =I3*F3 -> #N/A | K3: =IF(G3-5<0,3,0) -> #N/A | L3: =K3*F3 -> #N/A | M3: 24
A4: Hibiscus & Aloe Vera Organic Moisturizing Body Lotion - 30ml (Bloom) | B4: BC0002603002 | C4: BODY CARE | D4: =CEILING(J4,M4) -> #N/A | E4: =CEILING(L4,M4) -> #N/A | F4: {=XLOOKUP(B4,SALES!A:A,SALES!E:E)/12} -> 20.25 | G4: {=XLOOKUP(B4,'EXP INV'!Q:Q,'EXP INV'!R:R)} -> #N/A | H4: 8 | I4: =IF(G4<H4,10,0) -> #N/A | J4: =I4*F4 -> #N/A | K4: =IF(G4-5<0,3,0) -> #N/A | L4: =K4*F4 -> #N/A | M4: 32
A5: Hibiscus & Aloe Vera Organic Moisturizing Body Lotion - 100ml (Bloom) | B5: BC0002603102 | C5: BODY CARE | D5: =CEILING(J5,M5) -> #N/A | E5: =CEILING(L5,M5) -> #N/A | F5: {=XLOOKUP(B5,SALES!A:A,SALES!E:E)/12} -> 40.916667 | G5: {=XLOOKUP(B5,'EXP INV'!Q:Q,'EXP INV'!R:R)} -> #N/A | H5: 8 | I5: =IF(G5<H5,10,0) -> #N/A | J5: =I5*F5 -> #N/A | K5: =IF(G5-5<0,3,0) -> #N/A | L5: =K5*F5 -> #N/A | M5: 24
A6: US Bloom 24 Hours Organic Body Lotion (Extra Dry Skin) (100 ml) | B6: BC0002703102 | C6: BODY CARE | D6: =CEILING(J6,M6) -> #N/A | E6: =CEILING(L6,M6) -> #N/A | F6: {=XLOOKUP(B6,SALES!A:A,SALES!E:E)/12} -> 29.833333 | G6: {=XLOOKUP(B6,'EXP INV'!Q:Q,'EXP INV'!R:R)} -> #N/A | H6: 8 | I6: =IF(G6<H6,10,0) -> #N/A | J6: =I6*F6 -> #N/A | K6: =IF(G6-5<0,3,0) -> #N/A | L6: =K6*F6 -> #N/A | M6: 24
A7: US Bloom Refreshing & Age Defence Shower Gel (200 ml) | B7: BC0002803302 | C7: BODY CARE | D7: =CEILING(J7,M7) -> #N/A | E7: =CEILING(L7,M7) -> #N/A | F7: {=XLOOKUP(B7,SALES!A:A,SALES!E:E)/12} -> 14.416667 | G7: {=XLOOKUP(B7,'EXP INV'!Q:Q,'EXP INV'!R:R)} -> #N/A | H7: 8 | I7: =IF(G7<H7,10,0) -> #N/A | J7: =I7*F7 -> #N/A | K7: =IF(G7-5<0,3,0) -> #N/A | L7: =K7*F7 -> #N/A | M7: 24
A8: Neem & Tulsi Certified Organic Cleansing Face Wash - 30ml (Bloom) | B8: BC0002903002 | C8: BODY CARE | D8: =CEILING(J8,M8) -> #N/A | E8: =CEILING(L8,M8) -> #N/A | F8: {=XLOOKUP(B8,SALES!A:A,SALES!E:E)/12} -> 17 | G8: {=XLOOKUP(B8,'EXP INV'!Q:Q,'EXP INV'!R:R)} -> #N/A | H8: 8 | I8: =IF(G8<H8,10,0) -> #N/A | J8: =I8*F8 -> #N/A | K8: =IF(G8-5<0,3,0) -> #N/A | L8: =K8*F8 -> #N/A | M8: 32
A9: Neem & Tulsi Certified Organic Cleansing Face Wash - 100ml (Bloom) | B9: BC0002903102 | C9: BODY CARE | D9: =CEILING(J9,M9) -> #N/A | E9: =CEILING(L9,M9) -> #N/A | F9: {=XLOOKUP(B9,SALES!A:A,SALES!E:E)/12} -> 44.833333 | G9: {=XLOOKUP(B9,'EXP INV'!Q:Q,'EXP INV'!R:R)} -> #N/A | H9: 8 | I9: =IF(G9<H9,10,0) -> #N/A | J9: =I9*F9 -> #N/A | K9: =IF(G9-5<0,3,0) -> #N/A | L9: =K9*F9 -> #N/A | M9: 24
A10: Sandalwood and Turmeric Face Wash 30ml (Bloom) | B10: BC0003003002 | C10: BODY CARE | D10: =CEILING(J10,M10) -> #N/A | E10: =CEILING(L10,M10) -> #N/A | F10: {=XLOOKUP(B10,SALES!A:A,SALES!E:E)/12} -> 24.166667 | G10: {=XLOOKUP(B10,'EXP INV'!Q:Q,'EXP INV'!R:R)} -> #N/A | H10: 8 | I10: =IF(G10<H10,10,0) -> #N/A | J10: =I10*F10 -> #N/A | K10: =IF(G10-5<0,3,0) -> #N/A | L10: =K10*F10 -> #N/A | M10: 32
A11: Sandalwood and Turmeric Face Wash 100 ml (Bloom) | B11: BC0003003102 | C11: BODY CARE | D11: =CEILING(J11,M11) -> #N/A | E11: =CEILING(L11,M11) -> #N/A | F11: {=XLOOKUP(B11,SALES!A:A,SALES!E:E)/12} -> 40.333333 | G11: {=XLOOKUP(B11,'EXP INV'!Q:Q,'EXP INV'!R:R)} -> #N/A | H11: 8 | I11: =IF(G11<H11,10,0) -> #N/A | J11: =I11*F11 -> #N/A | K11: =IF(G11-5<0,3,0) -> #N/A | L11: =K11*F11 -> #N/A | M11: 24
A12: Shikakai & Jatamansi Certified Organic Strengthening Shampoo - 30ml (Bloom) | B12: BC0003503002 | C12: BODY CARE | D12: =CEILING(J12,M12) -> #N/A | E12: =CEILING(L12,M12) -> #N/A | F12: {=XLOOKUP(B12,SALES!A:A,SALES!E:E)/12} -> 28.5 | G12: {=XLOOKUP(B12,'EXP INV'!Q:Q,'EXP INV'!R:R)} -> #N/A | H12: 8 | I12: =IF(G12<H12,10,0) -> #N/A | J12: =I12*F12 -> #N/A | K12: =IF(G12-5<0,3,0) -> #N/A | L12: =K12*F12 -> #N/A | M12: 32
A13: Shikakai & Jatamansi Certified Organic Strengthening Shampoo - 200ml (Bloom) | B13: BC0003503302 | C13: BODY CARE | D13: =CEILING(J13,M13) -> #N/A | E13: =CEILING(L13,M13) -> #N/A | F13: {=XLOOKUP(B13,SALES!A:A,SALES!E:E)/12} -> 83.666667 | G13: {=XLOOKUP(B13,'EXP INV'!Q:Q,'EXP INV'!R:R)} -> #N/A | H13: 8 | I13: =IF(G13<H13,10,0) -> #N/A | J13: =I13*F13 -> #N/A | K13: =IF(G13-5<0,3,0) -> #N/A | L13: =K13*F13 -> #N/A | M13: 24
... A18: US Bloom Extra Nourishment & Protection Organic Shampoo (200 ml) | B18: BC0004203302 | C18: BODY CARE | D18: =CEILING(J18,M18) -> #N/A | E18: =CEILING(L18,M18) -> #N/A | F18: {=XLOOKUP(B18,SALES!A:A,SALES!E:E)/12} -> 22.333333 | G18: {=XLOOKUP(B18,'EXP INV'!Q:Q,'EXP INV'!R:R)} -> #N/A | H18: 8 | I18: =IF(G18<H18,10,0) -> #N/A | J18: =I18*F18 -> #N/A | K18: =IF(G18-5<0,3,0) -> #N/A | L18: =K18*F18 -> #N/A | M18: 24

Sheet AIR
A1: # | B1: NAME | C1: SKU | D1: CAT | E1: ORDER | F1: CAT | G1: MONTHLY SALES | H1: INV ON HAND | I1: MONTHS ON HAND | J1: MIN MOH | K1: ROUND | L1: CASE
A2: 1 | B2: Bhoomi-Bhuta-Shuddhi-3-month-supply | C2: YS0008305502 | D2: YOGA STORE | E2: =IF(J2-I2>0,(J2-I2)*G2,0) -> 820.66667 | F2: BHOOMI | G2: {=XLOOKUP(C2,SALES!A:A,SALES!E:E)/12} -> 205.33333 | H2: {=XLOOKUP(C2,INV!A:A,INV!G:G)} -> 206 | I2: =H2/G2 -> 1.0032468 | J2: 5 | K2: =ceiling(E2,L2) -> 840 | L2: 60
A3: 2 | B3: Gold Devi Pendant 16g Blk | C3: TC0003005500 | D3: CONX | E3: =IF((J3-I3)>0,(J3-I3)*G3,0) -> 1 | F3: GOLD | G3: {=XLOOKUP(C3,SALES!A:A,SALES!E:E)/12} -> 0.16666667 | H3: {=XLOOKUP(C3,INV!A:A,INV!G:G)} -> 0 | I3: =H3/G3 -> 0 | J3: 6 | K3: =CEILING(E3,1) -> 1 | L3: 1
A4: 3 | B4: Gold Devi Pendant 16g Red | C4: TC0003105500 | D4: CONX | E4: =IF((J4-I4)>0,(J4-I4)*G4,0) -> 2 | F4: GOLD | G4: {=XLOOKUP(C4,SALES!A:A,SALES!E:E)/12} -> 0.33333333 | H4: {=XLOOKUP(C4,INV!A:A,INV!G:G)} -> 0 | I4: =H4/G4 -> 0 | J4: 6 | K4: =CEILING(E4,1) -> 2 | L4: 1
A5: 4 | B5: Gold Devi Pendant 16g San | C5: TC0003205200 | D5: CONX | E5: =IF((J5-I5)>0,(J5-I5)*G5,0) -> 0 | F5: GOLD | G5: {=XLOOKUP(C5,SALES!A:A,SALES!E:E)/12} -> 0.33333333 | H5: {=XLOOKUP(C5,INV!A:A,INV!G:G)} -> 5 | I5: =H5/G5 -> 15 | J5: 6 | K5: =CEILING(E5,1) -> 0 | L5: 1
A6: 5 | B6: Gold Devi Pendant 24g Red | C6: TC0003105700 | D6: CONX | E6: =IF((J6-I6)>0,(J6-I6)*G6,0) -> 1.98 | F6: GOLD | G6: 0.33 | H6: {=XLOOKUP(C6,INV!A:A,INV!G:G)} -> 0 | I6: =H6/G6 -> 0 | J6: 6 | K6: =CEILING(E6,1) -> 2 | L6: 1
A7: 6 | B7: Gold Devi Pendant 24g San | C7: TC0003205500 | D7: CONX | E7: =IF((J7-I7)>0,(J7-I7)*G7,0) -> 1.98 | F7: GOLD | G7: 0.33 | H7: {=XLOOKUP(C7,INV!A:A,INV!G:G)} -> 0 | I7: =H7/G7 -> 0 | J7: 6 | K7: =CEILING(E7,1) -> 2 | L7: 1
A8: 7 | B8: Gold Devi Pendant 4g Blk | C8: TC0003005100 | D8: CONX | E8: =IF((J8-I8)>0,(J8-I8)*G8,0) -> 7.5 | F8: GOLD | G8: {=XLOOKUP(C8,SALES!A:A,SALES!E:E)/12} -> 1.25 | H8: {=XLOOKUP(C8,INV!A:A,INV!G:G)} -> 0 | I8: =H8/G8 -> 0 | J8: 6 | K8: =CEILING(E8,1) -> 8 | L8: 1
A9: 8 | B9: Gold Devi Pendant 4g Red | C9: TC0003105100 | D9: CONX | E9: =IF((J9-I9)>0,(J9-I9)*G9,0) -> 13 | F9: GOLD | G9: {=XLOOKUP(C9,SALES!A:A,SALES!E:E)/12} -> 2.1666667 | H9: {=XLOOKUP(C9,INV!A:A,INV!G:G)} -> 0 | I9: =H9/G9 -> 0 | J9: 6 | K9: =CEILING(E9,1) -> 13 | L9: 1
A10: 9 | B10: Gold Devi Pendant 4g San | C10: TC0003205700 | D10: CONX | E10: =IF((J10-I10)>0,(J10-I10)*G10,0) -> 9.5 | F10: GOLD | G10: {=XLOOKUP(C10,SALES!A:A,SALES!E:E)/12} -> 1.5833333 | H10: {=XLOOKUP(C10,INV!A:A,INV!G:G)} -> 0 | I10: =H10/G10 -> 0 | J10: 6 | K10: =CEILING(E10,1) -> 10 | L10: 1
A11: 10 | B11: Gold Devi Pendant 8g Blk | C11: TC0003005200 | D11: CONX | E11: =IF((J11-I11)>0,(J11-I11)*G11,0) -> 2 | F11: GOLD | G11: {=XLOOKUP(C11,SALES!A:A,SALES!E:E)/12} -> 0.5 | H11: {=XLOOKUP(C11,INV!A:A,INV!G:G)} -> 1 | I11: =H11/G11 -> 2 | J11: 6 | K11: =CEILING(E11,1) -> 2 | L11: 1
A12: 11 | B12: Gold Devi Pendant 8g Pln | C12: TC0002905200 | D12: CONX | E12: =IF((J12-I12)>0,(J12-I12)*G12,0) -> 6.5 | F12: GOLD | G12: {=XLOOKUP(C12,SALES!A:A,SALES!E:E)/12} -> 1.0833333 | H12: {=XLOOKUP(C12,INV!A:A,INV!G:G)} -> 0 | I12: =H12/G12 -> 0 | J12: 6 | K12: =CEILING(E12,1) -> 7 | L12: 1
A13: 12 | B13: Gold Devi Pendant 8g Red | C13: TC0003105200 | D13: CONX | E13: =IF((J13-I13)>0,(J13-I13)*G13,0) -> 4.5 | F13: GOLD | G13: {=XLOOKUP(C13,SALES!A:A,SALES!E:E)/12} -> 0.58333333 | H13: {=XLOOKUP(C13,INV!A:A,INV!G:G)} -> -1 | I13: =H13/G13 -> -1.7142857 | J13: 6 | K13: =CEILING(E13,1) -> 5 | L13: 1
A14: 13 | B14: Gold Devi Pendant 8g San | C14: TC0003205100 | D14: CONX | E14: =IF((J14-I14)>0,(J14-I14)*G14,0) -> 2 | F14: GOLD | G14: {=XLOOKUP(C14,SALES!A:A,SALES!E:E)/12} -> 0.33333333 | H14: {=XLOOKUP(C14,INV!A:A,INV!G:G)} -> 0 | I14: =H14/G14 -> 0 | J14: 6 | K14: =CEILING(E14,1) -> 2 | L14: 1
A15: 14 | B15: Gold Snake Ring (L) | C15: TC0007900400 | D15: CONX | E15: =IF((J15-I15)>0,(J15-I15)*G15,0) -> 0 | F15: GOLD | G15: {=XLOOKUP(C15,SALES!A:A,SALES!E:E)/12} -> 0.91666667 | H15: {=XLOOKUP(C15,INV!A:A,INV!G:G)} -> 8 | I15: =H15/G15 -> 8.7272727 | J15: 6 | K15: =CEILING(E15,1) -> 0 | L15: 1
A16: 15 | B16: Gold Snake Ring (M) | C16: TC0007900300 | D16: CONX | E16: =IF((J16-I16)>0,(J16-I16)*G16,0) -> 6.5 | F16: GOLD | G16: {=XLOOKUP(C16,SALES!A:A,SALES!E:E)/12} -> 1.0833333 | H16: {=XLOOKUP(C16,INV!A:A,INV!G:G)} -> 0 | I16: =H16/G16 -> 0 | J16: 6 | K16: =CEILING(E16,1) -> 7 | L16: 1
A17: 16 | B17: Gold Snake Ring (S) | C17: TC0007900200 | D17: CONX | E17: =IF((J17-I17)>0,(J17-I17)*G17,0) -> 9.5 | F17: GOLD | G17: {=XLOOKUP(C17,SALES!A:A,SALES!E:E)/12} -> 1.5833333 | H17: {=XLOOKUP(C17,INV!A:A,INV!G:G)} -> 0 | I17: =H17/G17 -> 0 | J17: 6 | K17: =CEILING(E17,1) -> 10 | L17: 1
A18: 17 | B18: Adiyogi-Ear-Rings-Silver | C18: CA0023000009 | D18: JEWELRY | E18: =IF((J18-I18)>0,(J18-I18)*G18,0) -> 0 | F18: SILVER | G18: {=XLOOKUP(C18,SALES!A:A,SALES!E:E)/12} -> 13.916667 | H18: {=XLOOKUP(C18,INV!A:A,INV!G:G)} -> 253 | I18: =H18/G18 -> 18.179641 | J18: 6 | K18: =CEILING(E18,1) -> 0 | L18: 1
A19: 18 | B19: Linga-Bhairavi-Chain-Silver | C19: CA0036000009 | D19: TEMPLE | E19: =IF((J19-I19)>0,(J19-I19)*G19,0) -> 0 | F19: SILVER | G19: {=XLOOKUP(C19,SALES!A:A,SALES!E:E)/12} -> 15.75 | H19: {=XLOOKUP(C19,INV!A:A,INV!G:G)} -> 247 | I19: =H19/G19 -> 15.68254 | J19: 6 | K19: =CEILING(E19,1) -> 0 | L19: 1
... A23: 22 | B23: Pure Silver (999) Aum Namahshivaya silver cuff | C23: CA0120000000 | D23: JEWELRY | E23: =IF((J23-I23)>0,(J23-I23)*G23,0) -> 0 | F23: SILVER | G23: {=XLOOKUP(C23,SALES!A:A,SALES!E:E)/12} -> 2.5833333 | H23: {=XLOOKUP(C23,INV!A:A,INV!G:G)} -> 142 | I23: =H23/G23 -> 54.967742 | J23: 6 | K23: =CEILING(E23,1) -> 0 | L23: 1
A24: 23 | B24: Antique hammered silver cuff | C24: CA0191600009 | D24: JEWELRY | E24: =IF((J24-I24)>0,(J24-I24)*G24,0) -> 0 | F24: SILVER | G24: 2 | H24: {=XLOOKUP(C24,INV!A:A,INV!G:G)} -> 46 | I24: =H24/G24 -> 23 | J24: 6 | K24: =CEILING(E24,1) -> 0 | L24: 1
A25: 24 | B25: Silver Sarpa earring | C25: CA0191900009 | D25: JEWELRY | E25: =IF((J25-I25)>0,(J25-I25)*G25,0) -> 35 | F25: SILVER | G25: 11 | H25: {=XLOOKUP(C25,INV!A:A,INV!G:G)} -> 31 | I25: =H25/G25 -> 2.8181818 | J25: 6 | K25: =CEILING(E25,1) -> 35 | L25: 1
A26: 25 | B26: Silver Devi Pendant (S) | C26: TC0003400209 | D26: CONX | E26: =IF((J26-I26)>0,(J26-I26)*G26,0) -> 0 | F26: SILVER | G26: {=XLOOKUP(C26,SALES!A:A,SALES!E:E)/12} -> 18.75 | H26: {=XLOOKUP(C26,INV!A:A,INV!G:G)} -> 633 | I26: =H26/G26 -> 33.76 | J26: 9 | K26: =CEILING(E26,1) -> 0 | L26: 1
A27: 26 | B27: Silver Devi Pendant (M) | C27: TC0003400309 | D27: CONX | E27: =IF((J27-I27)>0,(J27-I27)*G27,0) -> 0 | F27: SILVER | G27: {=XLOOKUP(C27,SALES!A:A,SALES!E:E)/12} -> 8.75 | H27: {=XLOOKUP(C27,INV!A:A,INV!G:G)} -> 494 | I27: =H27/G27 -> 56.457143 | J27: 9 | K27: =CEILING(E27,1) -> 0 | L27: 1
A28: 27 | B28: Linga-Bhairavi-Kumkum-Silver-Panel | C28: TC0011716900 | D28: CONX | E28: =IF((J28-I28)>0,(J28-I28)*G28,0) -> 0 | F28: SILVER | G28: {=XLOOKUP(C28,SALES!A:A,SALES!E:E)/12} -> 0.25 | H28: {=XLOOKUP(C28,INV!A:A,INV!G:G)} -> 20 | I28: =H28/G28 -> 80 | J28: 6 | K28: =CEILING(E28,1) -> 0 | L28: 1
A29: 28 | B29: Linga-Bhairavi-Turmeric-Silver-Panel | C29: TC0011717000 | D29: CONX | E29: =IF((J29-I29)>0,(J29-I29)*G29,0) -> 0 | F29: SILVER | G29: {=XLOOKUP(C29,SALES!A:A,SALES!E:E)/12} -> 0.33333333 | H29: {=XLOOKUP(C29,INV!A:A,INV!G:G)} -> 27 | I29: =H29/G29 -> 81 | J29: 6 | K29: =CEILING(E29,1) -> 0 | L29: 1
A30: 29 | B30: Metallic Devi Pendant | C30: TC0003500009 | D30: CONX | E30: =IF((J30-I30)>0,(J30-I30)*G30,0) -> 0 | F30: SILVER | G30: {=XLOOKUP(C30,SALES!A:A,SALES!E:E)/12} -> 24 | H30: {=XLOOKUP(C30,INV!A:A,INV!G:G)} -> 446 | I30: =H30/G30 -> 18.583333 | J30: 9 | K30: =CEILING(E30,1) -> 0 | L30: 1
A31: 30 | B31: Silver Snake Ring (S) | C31: TC0002200209 | D31: CONX | E31: =IF(I31<J31,12*G31,0) -> 0 | F31: SILVER | G31: =SUM('SN CALCS'!E15:E18) -> 4.8333333 | H31: {=xlookup(C31,INV!A:A,INV!G:G)+sum('SN CALCS'!F15:F18)} -> 187 | I31: =H31/G31 -> 38.689655 | J31: 6 | K31: =CEILING(E31,1) -> 0 | L31: 1
A32: 31 | B32: Silver Snake Ring (M) | C32: TC0002200309 | D32: CONX | E32: =IF(I32<J32,12*G32,0) -> 0 | F32: SILVER | G32: =SUM('SN CALCS'!E19:E20) -> 13.333333 | H32: {=xlookup(C32,INV!A:A,INV!G:G)+sum('SN CALCS'!F19:F20)} -> 483 | I32: =H32/G32 -> 36.225 | J32: 6 | K32: =CEILING(E32,1) -> 0 | L32: 1
A33: 32 | B33: Silver Snake Ring (L) | C33: TC0002200409 | D33: CONX | E33: =IF(I33<J33,12*G33,0) -> 0 | F33: SILVER | G33: =SUM('SN CALCS'!E21:E22) -> 19.333333 | H33: {=xlookup(C33,INV!A:A,INV!G:G)+sum('SN CALCS'!F21:F22)} -> 376 | I33: =H33/G33 -> 19.448276 | J33: 6 | K33: =CEILING(E33,1) -> 0 | L33: 1
A34: 33 | B34: Silver Snake Ring (XL) | C34: TC0002200509 | D34: CONX | E34: =IF(I34<J34,12*G34,0) -> 0 | F34: SILVER | G34: =SUM('SN CALCS'!E23:E24) -> 13.666667 | H34: {=xlookup(C34,INV!A:A,INV!G:G)+sum('SN CALCS'!F23:F24)} -> 417 | I34: =H34/G34 -> 30.512195 | J34: 6 | K34: =CEILING(E34,1) -> 0 | L34: 1
A35: 34 | B35: Silver Snake Ring (XXL) | C35: TC0002200609 | D35: CONX | E35: =IF(I35<J35,12*G35,0) -> 0 | F35: SILVER | G35: =SUM('SN CALCS'!E25:E27) -> 3.8333333 | H35: {=xlookup(C35,INV!A:A,INV!G:G)+SUM('SN CALCS'!F25:F27)} -> 219 | I35: =H35/G35 -> 57.130435 | J35: 6 | K35: =CEILING(E35,1) -> 0 | L35: 1

Sheet SEA
A1: Product/Name | B1: GLOBAL SKU | C1: CATEGORY | D1: ORDER LIST ? | E1: NOTES | F1: MON SALES | G1: INV OH | H1: MOH | I1: QTY REQ | J1: MTHS REQ | K1: OH MTH 1 | L1: OH MTH 2 | M1: OH MTH 3 | N1: OH MTH 4 | O1: OH MTH 5 | P1: OH MTH 6 | Q1: SEA QTY | R1: AIR SHIP? | S1: AIR QTY | T1: SEA SHIP | U1: AIR SHIP | V1: +1 MOH INC | W1: +2 MOH INC | X1: +3 MOH INC | Y1: +4 MOH INC | Z1: +5 MOH INC | AA1: +6 MOH INC
A2: Sanjeevini Health Mix 17.6oz | B2: NF0006106902 | C2: NATURAL FOOD | D2: {=XLOOKUP(B2,'ORDER LIST'!C:C,'ORDER LIST'!B:B)} -> Sanjeevini Health Mix 17.6oz | F2: {=XLOOKUP(B2,SALES!A:A,SALES!C:C)} -> 457.66667 | G2: =F2*H2 -> #N/A | H2: {=XLOOKUP(B2,'EXP INV'!Q:Q,'EXP INV'!R:R)} -> #N/A | I2: =F2*J2 -> 3661.3333 | J2: 8 | K2: =IF((H2-1+V2)<0,0,H2-1+V2) -> #N/A | L2: =IF((K2-1+W2)<0,0,K2-1+W2) -> #N/A | M2: =IF((L2-1+X2)<0,0,L2-1+X2) -> #N/A | N2: =IF((M2-1+Y2)<0,0,M2-1+Y2) -> #N/A | O2: =IF((N2-1+Z2)<0,0,N2-1+Z2) -> #N/A | P2: =IF((O2-1+AA2)<0,0,O2-1+AA2) -> #N/A | Q2: =T2*F2 -> #N/A | R2: X | S2: =U2*F2 -> #N/A | T2: =IF(P2<J2,J2-P2,0) -> #N/A | U2: =IF(N2<3,3-N2,0) -> #N/A | V2: {=iferror(XLOOKUP(B2,'INC INV'!AJ:AJ,'INC INV'!AL:AL)/F2,0)} -> 0 | W2: {=IFERROR(XLOOKUP(B2,'INC INV'!AP:AP,'INC INV'!AR:AR)/F2,0)} -> 0 | X2: {=IFERROR(XLOOKUP(B2,'INC INV'!AV:AV,'INC INV'!AX:AX)/F2,0)} -> 0 | Y2: {=IFERROR(XLOOKUP(B2,'INC INV'!BB:BB,'INC INV'!BD:BD)/F2,0)} -> 3.6970138 | Z2: {=IFERROR(XLOOKUP(B2,'INC INV'!BH:BH,'INC INV'!BJ:BJ)/F2,0)} -> 0 | AA2: {=IFERROR(XLOOKUP(B2,'INC INV'!BN:BN,'INC INV'!BP:BP)/F2,0)} -> 0
A3: Instant Sanjeevini 21oz | B3: NF0006207002 | C3: NATURAL FOOD | D3: {=XLOOKUP(B3,'ORDER LIST'!C:C,'ORDER LIST'!B:B)} -> Instant Sanjeevini 21oz | F3: {=XLOOKUP(B3,SALES!A:A,SALES!C:C)} -> 235.5 | G3: =F3*H3 -> #N/A | H3: {=XLOOKUP(B3,'EXP INV'!Q:Q,'EXP INV'!R:R)} -> #N/A | I3: =F3*J3 -> 1884 | J3: 8 | K3: =IF((H3-1+V3)<0,0,H3-1+V3) -> #N/A | L3: =IF((K3-1+W3)<0,0,K3-1+W3) -> #N/A | M3: =IF((L3-1+X3)<0,0,L3-1+X3) -> #N/A | N3: =IF((M3-1+Y3)<0,0,M3-1+Y3) -> #N/A | O3: =IF((N3-1+Z3)<0,0,N3-1+Z3) -> #N/A | P3: =IF((O3-1+AA3)<0,0,O3-1+AA3) -> #N/A | Q3: =T3*F3 -> #N/A | R3: X | S3: =U3*F3 -> #N/A | T3: =IF(P3<J3,J3-P3,0) -> #N/A | U3: =IF(N3<3,3-N3,0) -> #N/A | V3: {=iferror(XLOOKUP(B3,'INC INV'!AJ:AJ,'INC INV'!AL:AL)/F3,0)} -> 0 | W3: {=IFERROR(XLOOKUP(B3,'INC INV'!AP:AP,'INC INV'!AR:AR)/F3,0)} -> 0 | X3: {=IFERROR(XLOOKUP(B3,'INC INV'!AV:AV,'INC INV'!AX:AX)/F3,0)} -> 0 | Y3: {=IFERROR(XLOOKUP(B3,'INC INV'!BB:BB,'INC INV'!BD:BD)/F3,0)} -> 0.58598726 | Z3: {=IFERROR(XLOOKUP(B3,'INC INV'!BH:BH,'INC INV'!BJ:BJ)/F3,0)} -> 0 | AA3: {=IFERROR(XLOOKUP(B3,'INC INV'!BN:BN,'INC INV'!BP:BP)/F3,0)} -> 0
A4: Devi-Car-Hanging | B4: ME0018900000 | C4: ACCESSORY | F4: {=XLOOKUP(B4,SALES!A:A,SALES!C:C)} -> 67.25 | G4: {=XLOOKUP(B4,INV!A:A,INV!G:G)} -> 11 | H4: =IF(G4/F4<0,0,G4/F4) -> 0.16356877 | I4: =F4*J4 -> 403.5 | J4: 6 | K4: =IF((H4-1+V4)<0,0,H4-1+V4) -> 0 | L4: =IF((K4-1+W4)<0,0,K4-1+W4) -> 2.1821561 | M4: =IF((L4-1+X4)<0,0,L4-1+X4) -> 1.1821561 | N4: =IF((M4-1+Y4)<0,0,M4-1+Y4) -> 5.5204461 | O4: =IF((N4-1+Z4)<0,0,N4-1+Z4) -> 5.0408922 | P4: =IF((O4-1+AA4)<0,0,O4-1+AA4) -> 4.0408922 | Q4: =T4*F4 -> 131.75 | S4: =U4*F4 -> 0 | T4: =IF(P4<J4,J4-P4,0) -> 1.9591078 | U4: =IF(N4<3,3-N4,0) -> 0 | V4: {=iferror(XLOOKUP(B4,'INC INV'!AJ:AJ,'INC INV'!AL:AL)/F4,0)} -> 0 | W4: {=IFERROR(XLOOKUP(B4,'INC INV'!AP:AP,'INC INV'!AR:AR)/F4,0)} -> 3.1821561 | X4: {=IFERROR(XLOOKUP(B4,'INC INV'!AV:AV,'INC INV'!AX:AX)/F4,0)} -> 0 | Y4: {=IFERROR(XLOOKUP(B4,'INC INV'!BB:BB,'INC INV'!BD:BD)/F4,0)} -> 5.33829 | Z4: {=IFERROR(XLOOKUP(B4,'INC INV'!BH:BH,'INC INV'!BJ:BJ)/F4,0)} -> 0.5204461 | AA4: {=IFERROR(XLOOKUP(B4,'INC INV'!BN:BN,'INC INV'!BP:BP)/F4,0)} -> 0
A5: Adiyogi miniature 2" car stand - Black | B5: ME0037600000 | C5: ACCESSORY | F5: {=XLOOKUP(B5,SALES!A:A,SALES!C:C)} -> 50.416667 | G5: {=XLOOKUP(B5,INV!A:A,INV!G:G)} -> 0 | H5: =IF(G5/F5<0,0,G5/F5) -> 0 | I5: =F5*J5 -> 302.5 | J5: 6 | K5: =IF((H5-1+V5)<0,0,H5-1+V5) -> 0 | L5: =IF((K5-1+W5)<0,0,K5-1+W5) -> 1.8165289 | M5: =IF((L5-1+X5)<0,0,L5-1+X5) -> 0.81652893 | N5: =IF((M5-1+Y5)<0,0,M5-1+Y5) -> 5.4495868 | O5: =IF((N5-1+Z5)<0,0,N5-1+Z5) -> 5.0446281 | P5: =IF((O5-1+AA5)<0,0,O5-1+AA5) -> 4.0446281 | Q5: =T5*F5 -> 98.583333 | S5: =U5*F5 -> 0 | T5: =IF(P5<J5,J5-P5,0) -> 1.9553719 | U5: =IF(N5<3,3-N5,0) -> 0 | V5: {=iferror(XLOOKUP(B5,'INC INV'!AJ:AJ,'INC INV'!AL:AL)/F5,0)} -> 0 | W5: {=IFERROR(XLOOKUP(B5,'INC INV'!AP:AP,'INC INV'!AR:AR)/F5,0)} -> 2.8165289 | X5: {=IFERROR(XLOOKUP(B5,'INC INV'!AV:AV,'INC INV'!AX:AX)/F5,0)} -> 0 | Y5: {=IFERROR(XLOOKUP(B5,'INC INV'!BB:BB,'INC INV'!BD:BD)/F5,0)} -> 5.6330579 | Z5: {=IFERROR(XLOOKUP(B5,'INC INV'!BH:BH,'INC INV'!BJ:BJ)/F5,0)} -> 0.59504132 | AA5: {=IFERROR(XLOOKUP(B5,'INC INV'!BN:BN,'INC INV'!BP:BP)/F5,0)} -> 0
A6: Jasmine Orient Solid Perfume | B6: BC0001005100 | C6: BODY CARE | D6: {=XLOOKUP(B6,'ORDER LIST'!C:C,'ORDER LIST'!B:B)} -> Jasmine Orient Solid Perfume | F6: {=XLOOKUP(B6,SALES!A:A,SALES!C:C)} -> 82.5 | G6: {=XLOOKUP(B6,INV!A:A,INV!G:G)} -> 1 | H6: =IF(G6/F6<0,0,G6/F6) -> 0.012121212 | I6: =F6*J6 -> 660 | J6: 8 | K6: =IF((H6-1+V6)<0,0,H6-1+V6) -> 0 | L6: =IF((K6-1+W6)<0,0,K6-1+W6) -> 9.3757576 | M6: =IF((L6-1+X6)<0,0,L6-1+X6) -> 8.3757576 | N6: =IF((M6-1+Y6)<0,0,M6-1+Y6) -> 9.169697 | O6: =IF((N6-1+Z6)<0,0,N6-1+Z6) -> 8.169697 | P6: =IF((O6-1+AA6)<0,0,O6-1+AA6) -> 7.169697 | Q6: =T6*F6 -> 68.5 | S6: =U6*F6 -> 0 | T6: =IF(P6<J6,J6-P6,0) -> 0.83030303 | U6: =IF(N6<3,3-N6,0) -> 0 | V6: {=iferror(XLOOKUP(B6,'INC INV'!AJ:AJ,'INC INV'!AL:AL)/F6,0)} -> 0 | W6: {=IFERROR(XLOOKUP(B6,'INC INV'!AP:AP,'INC INV'!AR:AR)/F6,0)} -> 10.375758 | X6: {=IFERROR(XLOOKUP(B6,'INC INV'!AV:AV,'INC INV'!AX:AX)/F6,0)} -> 0 | Y6: {=IFERROR(XLOOKUP(B6,'INC INV'!BB:BB,'INC INV'!BD:BD)/F6,0)} -> 1.7939394 | Z6: {=IFERROR(XLOOKUP(B6,'INC INV'!BH:BH,'INC INV'!BJ:BJ)/F6,0)} -> 0 | AA6: {=IFERROR(XLOOKUP(B6,'INC INV'!BN:BN,'INC INV'!BP:BP)/F6,0)} -> 0
A7: Copper Devi Pendant | B7: TC0003300409 | C7: CONX | E7: L, HOLDING OFF ORDERING BECAUSE WE HAVE SO MUCH STOCK OF THE S AND M, M IS DISCONTINUED | F7: 30 | G7: {=XLOOKUP(B7,INV!A:A,INV!G:G)} -> 0 | H7: =IF(G7/F7<0,0,G7/F7) -> 0 | I7: =F7*J7 -> 300 | J7: 10 | K7: =IF((H7-1+V7)<0,0,H7-1+V7) -> 0 | L7: =IF((K7-1+W7)<0,0,K7-1+W7) -> 0 | M7: =IF((L7-1+X7)<0,0,L7-1+X7) -> 0 | N7: =IF((M7-1+Y7)<0,0,M7-1+Y7) -> 0 | O7: =IF((N7-1+Z7)<0,0,N7-1+Z7) -> 9 | P7: =IF((O7-1+AA7)<0,0,O7-1+AA7) -> 8 | Q7: =T7*F7 -> 60 | S7: =U7*F7 -> 90 | T7: =IF(P7<J7,J7-P7,0) -> 2 | U7: =IF(N7<3,3-N7,0) -> 3 | V7: {=iferror(XLOOKUP(B7,'INC INV'!AJ:AJ,'INC INV'!AL:AL)/F7,0)} -> 0 | W7: {=IFERROR(XLOOKUP(B7,'INC INV'!AP:AP,'INC INV'!AR:AR)/F7,0)} -> 0 | X7: {=IFERROR(XLOOKUP(B7,'INC INV'!AV:AV,'INC INV'!AX:AX)/F7,0)} -> 0 | Y7: {=IFERROR(XLOOKUP(B7,'INC INV'!BB:BB,'INC INV'!BD:BD)/F7,0)} -> 0.033333333 | Z7: {=IFERROR(XLOOKUP(B7,'INC INV'!BH:BH,'INC INV'!BJ:BJ)/F7,0)} -> 10 | AA7: {=IFERROR(XLOOKUP(B7,'INC INV'!BN:BN,'INC INV'!BP:BP)/F7,0)} -> 0
A8: Instant Sanjeevini 20 kg Bag | B8: NF0006220902 | C8: NATURAL FOOD | F8: 6 | G8: {=XLOOKUP(B8,INV!A:A,INV!G:G)} -> 0 | H8: =IF(G8/F8<0,0,G8/F8) -> 0 | I8: =F8*J8 -> 48 | J8: 8 | K8: =IF((H8-1+V8)<0,0,H8-1+V8) -> 0 | L8: =IF((K8-1+W8)<0,0,K8-1+W8) -> 0 | M8: =IF((L8-1+X8)<0,0,L8-1+X8) -> 0 | N8: =IF((M8-1+Y8)<0,0,M8-1+Y8) -> 0 | O8: =IF((N8-1+Z8)<0,0,N8-1+Z8) -> 0 | P8: =IF((O8-1+AA8)<0,0,O8-1+AA8) -> 0 | Q8: =T8*F8 -> 48 | S8: =U8*F8 -> 18 | T8: =IF(P8<J8,J8-P8,0) -> 8 | U8: =IF(N8<3,3-N8,0) -> 3 | V8: {=iferror(XLOOKUP(B8,'INC INV'!AJ:AJ,'INC INV'!AL:AL)/F8,0)} -> 0 | W8: {=IFERROR(XLOOKUP(B8,'INC INV'!AP:AP,'INC INV'!AR:AR)/F8,0)} -> 0 | X8: {=IFERROR(XLOOKUP(B8,'INC INV'!AV:AV,'INC INV'!AX:AX)/F8,0)} -> 0 | Y8: {=IFERROR(XLOOKUP(B8,'INC INV'!BB:BB,'INC INV'!BD:BD)/F8,0)} -> 0 | Z8: {=IFERROR(XLOOKUP(B8,'INC INV'!BH:BH,'INC INV'!BJ:BJ)/F8,0)} -> 0 | AA8: {=IFERROR(XLOOKUP(B8,'INC INV'!BN:BN,'INC INV'!BP:BP)/F8,0)} -> 0
A9: Relax Solid Perfume | B9: BC0001205100 | C9: BODY CARE | D9: {=XLOOKUP(B9,'ORDER LIST'!C:C,'ORDER LIST'!B:B)} -> Relax Solid Perfume | F9: {=XLOOKUP(B9,SALES!A:A,SALES!C:C)} -> 41.75 | G9: {=XLOOKUP(B9,INV!A:A,INV!G:G)} -> -3 | H9: =IF(G9/F9<0,0,G9/F9) -> 0 | I9: =F9*J9 -> 334 | J9: 8 | K9: =IF((H9-1+V9)<0,0,H9-1+V9) -> 0 | L9: =IF((K9-1+W9)<0,0,K9-1+W9) -> 10.065868 | M9: =IF((L9-1+X9)<0,0,L9-1+X9) -> 9.0658683 | N9: =IF((M9-1+Y9)<0,0,M9-1+Y9) -> 9.1676647 | O9: =IF((N9-1+Z9)<0,0,N9-1+Z9) -> 8.1676647 | P9: =IF((O9-1+AA9)<0,0,O9-1+AA9) -> 7.1676647 | Q9: =T9*F9 -> 34.75 | S9: =U9*F9 -> 0 | T9: =IF(P9<J9,J9-P9,0) -> 0.83233533 | U9: =IF(N9<3,3-N9,0) -> 0 | V9: {=iferror(XLOOKUP(B9,'INC INV'!AJ:AJ,'INC INV'!AL:AL)/F9,0)} -> 0 | W9: {=IFERROR(XLOOKUP(B9,'INC INV'!AP:AP,'INC INV'!AR:AR)/F9,0)} -> 11.065868 | X9: {=IFERROR(XLOOKUP(B9,'INC INV'!AV:AV,'INC INV'!AX:AX)/F9,0)} -> 0 | Y9: {=IFERROR(XLOOKUP(B9,'INC INV'!BB:BB,'INC INV'!BD:BD)/F9,0)} -> 1.1017964 | Z9: {=IFERROR(XLOOKUP(B9,'INC INV'!BH:BH,'INC INV'!BJ:BJ)/F9,0)} -> 0 | AA9: {=IFERROR(XLOOKUP(B9,'INC INV'!BN:BN,'INC INV'!BP:BP)/F9,0)} -> 0
A10: Adiyogi Bucket Hat - Navy Blue L | B10: CA0154800400 | C10: ACCESSORY | F10: 15 | G10: 0 | H10: =IF(G10/F10<0,0,G10/F10) -> 0 | I10: =F10*J10 -> 90 | J10: 6 | K10: =IF((H10-1+V10)<0,0,H10-1+V10) -> 0 | L10: =IF((K10-1+W10)<0,0,K10-1+W10) -> 0 | M10: =IF((L10-1+X10)<0,0,L10-1+X10) -> 0 | N10: =IF((M10-1+Y10)<0,0,M10-1+Y10) -> 0 | O10: =IF((N10-1+Z10)<0,0,N10-1+Z10) -> 5 | P10: =IF((O10-1+AA10)<0,0,O10-1+AA10) -> 4 | Q10: =T10*F10 -> 30 | S10: =U10*F10 -> 45 | T10: =IF(P10<J10,J10-P10,0) -> 2 | U10: =IF(N10<3,3-N10,0) -> 3 | V10: {=iferror(XLOOKUP(B10,'INC INV'!AJ:AJ,'INC INV'!AL:AL)/F10,0)} -> 0 | W10: {=IFERROR(XLOOKUP(B10,'INC INV'!AP:AP,'INC INV'!AR:AR)/F10,0)} -> 0 | X10: {=IFERROR(XLOOKUP(B10,'INC INV'!AV:AV,'INC INV'!AX:AX)/F10,0)} -> 0 | Y10: {=IFERROR(XLOOKUP(B10,'INC INV'!BB:BB,'INC INV'!BD:BD)/F10,0)} -> 0 | Z10: {=IFERROR(XLOOKUP(B10,'INC INV'!BH:BH,'INC INV'!BJ:BJ)/F10,0)} -> 6 | AA10: {=IFERROR(XLOOKUP(B10,'INC INV'!BN:BN,'INC INV'!BP:BP)/F10,0)} -> 0
A11: Adiyogi Bucket Hat - Beige L | B11: CA0154900400 | C11: ACCESSORY | F11: 15 | G11: 0 | H11: =IF(G11/F11<0,0,G11/F11) -> 0 | I11: =F11*J11 -> 90 | J11: 6 | K11: =IF((H11-1+V11)<0,0,H11-1+V11) -> 0 | L11: =IF((K11-1+W11)<0,0,K11-1+W11) -> 0 | M11: =IF((L11-1+X11)<0,0,L11-1+X11) -> 0 | N11: =IF((M11-1+Y11)<0,0,M11-1+Y11) -> 0 | O11: =IF((N11-1+Z11)<0,0,N11-1+Z11) -> 5 | P11: =IF((O11-1+AA11)<0,0,O11-1+AA11) -> 4 | Q11: =T11*F11 -> 30 | S11: =U11*F11 -> 45 | T11: =IF(P11<J11,J11-P11,0) -> 2 | U11: =IF(N11<3,3-N11,0) -> 3 | V11: {=iferror(XLOOKUP(B11,'INC INV'!AJ:AJ,'INC INV'!AL:AL)/F11,0)} -> 0 | W11: {=IFERROR(XLOOKUP(B11,'INC INV'!AP:AP,'INC INV'!AR:AR)/F11,0)} -> 0 | X11: {=IFERROR(XLOOKUP(B11,'INC INV'!AV:AV,'INC INV'!AX:AX)/F11,0)} -> 0 | Y11: {=IFERROR(XLOOKUP(B11,'INC INV'!BB:BB,'INC INV'!BD:BD)/F11,0)} -> 0 | Z11: {=IFERROR(XLOOKUP(B11,'INC INV'!BH:BH,'INC INV'!BJ:BJ)/F11,0)} -> 6 | AA11: {=IFERROR(XLOOKUP(B11,'INC INV'!BN:BN,'INC INV'!BP:BP)/F11,0)} -> 0
A12: Devi Journal (Tree free Banana Paper) | B12: HO0108200000 | C12: ACCESSORY | F12: 15 | G12: 0 | H12: =IF(G12/F12<0,0,G12/F12) -> 0 | I12: =F12*J12 -> 90 | J12: 6 | K12: =IF((H12-1+V12)<0,0,H12-1+V12) -> 0 | L12: =IF((K12-1+W12)<0,0,K12-1+W12) -> 0 | M12: =IF((L12-1+X12)<0,0,L12-1+X12) -> 0 | N12: =IF((M12-1+Y12)<0,0,M12-1+Y12) -> 5 | O12: =IF((N12-1+Z12)<0,0,N12-1+Z12) -> 5 | P12: =IF((O12-1+AA12)<0,0,O12-1+AA12) -> 4 | Q12: =T12*F12 -> 30 | S12: =U12*F12 -> 0 | T12: =IF(P12<J12,J12-P12,0) -> 2 | U12: =IF(N12<3,3-N12,0) -> 0 | V12: {=iferror(XLOOKUP(B12,'INC INV'!AJ:AJ,'INC INV'!AL:AL)/F12,0)} -> 0 | W12: {=IFERROR(XLOOKUP(B12,'INC INV'!AP:AP,'INC INV'!AR:AR)/F12,0)} -> 0 | X12: {=IFERROR(XLOOKUP(B12,'INC INV'!AV:AV,'INC INV'!AX:AX)/F12,0)} -> 0 | Y12: {=IFERROR(XLOOKUP(B12,'INC INV'!BB:BB,'INC INV'!BD:BD)/F12,0)} -> 6 | Z12: {=IFERROR(XLOOKUP(B12,'INC INV'!BH:BH,'INC INV'!BJ:BJ)/F12,0)} -> 1 | AA12: {=IFERROR(XLOOKUP(B12,'INC INV'!BN:BN,'INC INV'!BP:BP)/F12,0)} -> 0
A13: Copper Mug with Handle, 414 ml | B13: YS0002300002 | C13: COPPER | F13: 15 | G13: 0 | H13: =IF(G13/F13<0,0,G13/F13) -> 0 | I13: =F13*J13 -> 120 | J13: 8 | K13: =IF((H13-1+V13)<0,0,H13-1+V13) -> 0 | L13: =IF((K13-1+W13)<0,0,K13-1+W13) -> 0 | M13: =IF((L13-1+X13)<0,0,L13-1+X13) -> 0 | N13: =IF((M13-1+Y13)<0,0,M13-1+Y13) -> 7 | O13: =IF((N13-1+Z13)<0,0,N13-1+Z13) -> 7 | P13: =IF((O13-1+AA13)<0,0,O13-1+AA13) -> 6 | Q13: =T13*F13 -> 30 | S13: =U13*F13 -> 0 | T13: =IF(P13<J13,J13-P13,0) -> 2 | U13: =IF(N13<3,3-N13,0) -> 0 | V13: {=iferror(XLOOKUP(B13,'INC INV'!AJ:AJ,'INC INV'!AL:AL)/F13,0)} -> 0 | W13: {=IFERROR(XLOOKUP(B13,'INC INV'!AP:AP,'INC INV'!AR:AR)/F13,0)} -> 0 | X13: {=IFERROR(XLOOKUP(B13,'INC INV'!AV:AV,'INC INV'!AX:AX)/F13,0)} -> 0 | Y13: {=IFERROR(XLOOKUP(B13,'INC INV'!BB:BB,'INC INV'!BD:BD)/F13,0)} -> 8 | Z13: {=IFERROR(XLOOKUP(B13,'INC INV'!BH:BH,'INC INV'!BJ:BJ)/F13,0)} -> 1 | AA13: {=IFERROR(XLOOKUP(B13,'INC INV'!BN:BN,'INC INV'!BP:BP)/F13,0)} -> 0
A14: Traditional Copper Drinkware Pot Style 2 | B14: YS0018200000 | C14: COPPER | F14: 15 | G14: 0 | H14: =IF(G14/F14<0,0,G14/F14) -> 0 | I14: =F14*J14 -> 120 | J14: 8 | K14: =IF((H14-1+V14)<0,0,H14-1+V14) -> 0 | L14: =IF((K14-1+W14)<0,0,K14-1+W14) -> 0 | M14: =IF((L14-1+X14)<0,0,L14-1+X14) -> 0 | N14: =IF((M14-1+Y14)<0,0,M14-1+Y14) -> 7 | O14: =IF((N14-1+Z14)<0,0,N14-1+Z14) -> 7 | P14: =IF((O14-1+AA14)<0,0,O14-1+AA14) -> 6 | Q14: =T14*F14 -> 30 | S14: =U14*F14 -> 0 | T14: =IF(P14<J14,J14-P14,0) -> 2 | U14: =IF(N14<3,3-N14,0) -> 0 | V14: {=iferror(XLOOKUP(B14,'INC INV'!AJ:AJ,'INC INV'!AL:AL)/F14,0)} -> 0 | W14: {=IFERROR(XLOOKUP(B14,'INC INV'!AP:AP,'INC INV'!AR:AR)/F14,0)} -> 0 | X14: {=IFERROR(XLOOKUP(B14,'INC INV'!AV:AV,'INC INV'!AX:AX)/F14,0)} -> 0 | Y14: {=IFERROR(XLOOKUP(B14,'INC INV'!BB:BB,'INC INV'!BD:BD)/F14,0)} -> 8 | Z14: {=IFERROR(XLOOKUP(B14,'INC INV'!BH:BH,'INC INV'!BJ:BJ)/F14,0)} -> 1 | AA14: {=IFERROR(XLOOKUP(B14,'INC INV'!BN:BN,'INC INV'!BP:BP)/F14,0)} -> 0
A15: Copper Sipper Bottle - 700 Ml | B15: YS0018400000 | C15: COPPER | F15: 15 | G15: 0 | H15: =IF(G15/F15<0,0,G15/F15) -> 0 | I15: =F15*J15 -> 120 | J15: 8 | K15: =IF((H15-1+V15)<0,0,H15-1+V15) -> 0 | L15: =IF((K15-1+W15)<0,0,K15-1+W15) -> 0 | M15: =IF((L15-1+X15)<0,0,L15-1+X15) -> 0 | N15: =IF((M15-1+Y15)<0,0,M15-1+Y15) -> 7 | O15: =IF((N15-1+Z15)<0,0,N15-1+Z15) -> 7 | P15: =IF((O15-1+AA15)<0,0,O15-1+AA15) -> 6 | Q15: =T15*F15 -> 30 | S15: =U15*F15 -> 0 | T15: =IF(P15<J15,J15-P15,0) -> 2 | U15: =IF(N15<3,3-N15,0) -> 0 | V15: {=iferror(XLOOKUP(B15,'INC INV'!AJ:AJ,'INC INV'!AL:AL)/F15,0)} -> 0 | W15: {=IFERROR(XLOOKUP(B15,'INC INV'!AP:AP,'INC INV'!AR:AR)/F15,0)} -> 0 | X15: {=IFERROR(XLOOKUP(B15,'INC INV'!AV:AV,'INC INV'!AX:AX)/F15,0)} -> 0 | Y15: {=IFERROR(XLOOKUP(B15,'INC INV'!BB:BB,'INC INV'!BD:BD)/F15,0)} -> 8 | Z15: {=IFERROR(XLOOKUP(B15,'INC INV'!BH:BH,'INC INV'!BJ:BJ)/F15,0)} -> 1 | AA15: {=IFERROR(XLOOKUP(B15,'INC INV'!BN:BN,'INC INV'!BP:BP)/F15,0)} -> 0
A16: Copper Water Bottle 350 ml (Hammered) | B16: YS0018900000 | C16: COPPER | F16: 15 | G16: 0 | H16: =IF(G16/F16<0,0,G16/F16) -> 0 | I16: =F16*J16 -> 120 | J16: 8 | K16: =IF((H16-1+V16)<0,0,H16-1+V16) -> 0 | L16: =IF((K16-1+W16)<0,0,K16-1+W16) -> 0 | M16: =IF((L16-1+X16)<0,0,L16-1+X16) -> 0 | N16: =IF((M16-1+Y16)<0,0,M16-1+Y16) -> 7 | O16: =IF((N16-1+Z16)<0,0,N16-1+Z16) -> 7 | P16: =IF((O16-1+AA16)<0,0,O16-1+AA16) -> 6 | Q16: =T16*F16 -> 30 | S16: =U16*F16 -> 0 | T16: =IF(P16<J16,J16-P16,0) -> 2 | U16: =IF(N16<3,3-N16,0) -> 0 | V16: {=iferror(XLOOKUP(B16,'INC INV'!AJ:AJ,'INC INV'!AL:AL)/F16,0)} -> 0 | W16: {=IFERROR(XLOOKUP(B16,'INC INV'!AP:AP,'INC INV'!AR:AR)/F16,0)} -> 0 | X16: {=IFERROR(XLOOKUP(B16,'INC INV'!AV:AV,'INC INV'!AX:AX)/F16,0)} -> 0 | Y16: {=IFERROR(XLOOKUP(B16,'INC INV'!BB:BB,'INC INV'!BD:BD)/F16,0)} -> 8 | Z16: {=IFERROR(XLOOKUP(B16,'INC INV'!BH:BH,'INC INV'!BJ:BJ)/F16,0)} -> 1 | AA16: {=IFERROR(XLOOKUP(B16,'INC INV'!BN:BN,'INC INV'!BP:BP)/F16,0)} -> 0
A17: Copper Vibhuti Box (Small) - Padam | B17: HO0108417000 | C17: TEMPLE | F17: 15 | G17: {=XLOOKUP(B17,INV!A:A,INV!G:G)} -> 0 | H17: =IF(G17/F17<0,0,G17/F17) -> 0 | I17: =F17*J17 -> 120 | J17: 8 | K17: =IF((H17-1+V17)<0,0,H17-1+V17) -> 0 | L17: =IF((K17-1+W17)<0,0,K17-1+W17) -> 0 | M17: =IF((L17-1+X17)<0,0,L17-1+X17) -> 0 | N17: =IF((M17-1+Y17)<0,0,M17-1+Y17) -> 7 | O17: =IF((N17-1+Z17)<0,0,N17-1+Z17) -> 7 | P17: =IF((O17-1+AA17)<0,0,O17-1+AA17) -> 6 | Q17: =T17*F17 -> 30 | S17: =U17*F17 -> 0 | T17: =IF(P17<J17,J17-P17,0) -> 2 | U17: =IF(N17<3,3-N17,0) -> 0 | V17: {=iferror(XLOOKUP(B17,'INC INV'!AJ:AJ,'INC INV'!AL:AL)/F17,0)} -> 0 | W17: {=IFERROR(XLOOKUP(B17,'INC INV'!AP:AP,'INC INV'!AR:AR)/F17,0)} -> 0 | X17: {=IFERROR(XLOOKUP(B17,'INC INV'!AV:AV,'INC INV'!AX:AX)/F17,0)} -> 0 | Y17: {=IFERROR(XLOOKUP(B17,'INC INV'!BB:BB,'INC INV'!BD:BD)/F17,0)} -> 8 | Z17: {=IFERROR(XLOOKUP(B17,'INC INV'!BH:BH,'INC INV'!BJ:BJ)/F17,0)} -> 1 | AA17: {=IFERROR(XLOOKUP(B17,'INC INV'!BN:BN,'INC INV'!BP:BP)/F17,0)} -> 0
A18: Copper Vibhuti Box (Tall) - Trigun | B18: HO0108617000 | C18: TEMPLE | F18: 15 | G18: {=XLOOKUP(B18,INV!A:A,INV!G:G)} -> 0 | H18: =IF(G18/F18<0,0,G18/F18) -> 0 | I18: =F18*J18 -> 120 | J18: 8 | K18: =IF((H18-1+V18)<0,0,H18-1+V18) -> 0 | L18: =IF((K18-1+W18)<0,0,K18-1+W18) -> 0 | M18: =IF((L18-1+X18)<0,0,L18-1+X18) -> 0 | N18: =IF((M18-1+Y18)<0,0,M18-1+Y18) -> 7 | O18: =IF((N18-1+Z18)<0,0,N18-1+Z18) -> 7 | P18: =IF((O18-1+AA18)<0,0,O18-1+AA18) -> 6 | Q18: =T18*F18 -> 30 | S18: =U18*F18 -> 0 | T18: =IF(P18<J18,J18-P18,0) -> 2 | U18: =IF(N18<3,3-N18,0) -> 0 | V18: {=iferror(XLOOKUP(B18,'INC INV'!AJ:AJ,'INC INV'!AL:AL)/F18,0)} -> 0 | W18: {=IFERROR(XLOOKUP(B18,'INC INV'!AP:AP,'INC INV'!AR:AR)/F18,0)} -> 0 | X18: {=IFERROR(XLOOKUP(B18,'INC INV'!AV:AV,'INC INV'!AX:AX)/F18,0)} -> 0 | Y18: {=IFERROR(XLOOKUP(B18,'INC INV'!BB:BB,'INC INV'!BD:BD)/F18,0)} -> 8 | Z18: {=IFERROR(XLOOKUP(B18,'INC INV'!BH:BH,'INC INV'!BJ:BJ)/F18,0)} -> 1 | AA18: {=IFERROR(XLOOKUP(B18,'INC INV'!BN:BN,'INC INV'!BP:BP)/F18,0)} -> 0
A19: Adiyogi Galactic - Printed Notebook | B19: HO0088917200 | C19: ACCESSORY | F19: 10 | G19: 0 | H19: =IF(G19/F19<0,0,G19/F19) -> 0 | I19: =F19*J19 -> 60 | J19: 6 | K19: =IF((H19-1+V19)<0,0,H19-1+V19) -> 0 | L19: =IF((K19-1+W19)<0,0,K19-1+W19) -> 0 | M19: =IF((L19-1+X19)<0,0,L19-1+X19) -> 0 | N19: =IF((M19-1+Y19)<0,0,M19-1+Y19) -> 5 | O19: =IF((N19-1+Z19)<0,0,N19-1+Z19) -> 5 | P19: =IF((O19-1+AA19)<0,0,O19-1+AA19) -> 4 | Q19: =T19*F19 -> 20 | S19: =U19*F19 -> 0 | T19: =IF(P19<J19,J19-P19,0) -> 2 | U19: =IF(N19<3,3-N19,0) -> 0 | V19: {=iferror(XLOOKUP(B19,'INC INV'!AJ:AJ,'INC INV'!AL:AL)/F19,0)} -> 0 | W19: {=IFERROR(XLOOKUP(B19,'INC INV'!AP:AP,'INC INV'!AR:AR)/F19,0)} -> 0 | X19: {=IFERROR(XLOOKUP(B19,'INC INV'!AV:AV,'INC INV'!AX:AX)/F19,0)} -> 0 | Y19: {=IFERROR(XLOOKUP(B19,'INC INV'!BB:BB,'INC INV'!BD:BD)/F19,0)} -> 6 | Z19: {=IFERROR(XLOOKUP(B19,'INC INV'!BH:BH,'INC INV'!BJ:BJ)/F19,0)} -> 1 | AA19: {=IFERROR(XLOOKUP(B19,'INC INV'!BN:BN,'INC INV'!BP:BP)/F19,0)} -> 0
A20: Adiyogi Glow-in-the-Dark Keychain (hues of slendour) | B20: HO0125900000 | C20: ACCESSORY | F20: 10 | G20: 0 | H20: =IF(G20/F20<0,0,G20/F20) -> 0 | I20: =F20*J20 -> 60 | J20: 6 | K20: =IF((H20-1+V20)<0,0,H20-1+V20) -> 0 | L20: =IF((K20-1+W20)<0,0,K20-1+W20) -> 0 | M20: =IF((L20-1+X20)<0,0,L20-1+X20) -> 0 | N20: =IF((M20-1+Y20)<0,0,M20-1+Y20) -> 5 | O20: =IF((N20-1+Z20)<0,0,N20-1+Z20) -> 5 | P20: =IF((O20-1+AA20)<0,0,O20-1+AA20) -> 4 | Q20: =T20*F20 -> 20 | S20: =U20*F20 -> 0 | T20: =IF(P20<J20,J20-P20,0) -> 2 | U20: =IF(N20<3,3-N20,0) -> 0 | V20: {=iferror(XLOOKUP(B20,'INC INV'!AJ:AJ,'INC INV'!AL:AL)/F20,0)} -> 0 | W20: {=IFERROR(XLOOKUP(B20,'INC INV'!AP:AP,'INC INV'!AR:AR)/F20,0)} -> 0 | X20: {=IFERROR(XLOOKUP(B20,'INC INV'!AV:AV,'INC INV'!AX:AX)/F20,0)} -> 0 | Y20: {=IFERROR(XLOOKUP(B20,'INC INV'!BB:BB,'INC INV'!BD:BD)/F20,0)} -> 6 | Z20: {=IFERROR(XLOOKUP(B20,'INC INV'!BH:BH,'INC INV'!BJ:BJ)/F20,0)} -> 1 | AA20: {=IFERROR(XLOOKUP(B20,'INC INV'!BN:BN,'INC INV'!BP:BP)/F20,0)} -> 0
